Workbook

Sheet README
A1: Stride: Financial Model
A3: 10-year operating model, three statements, and a valuation. EUR. Y1 = 2027.
A5: COLOUR CODE
A6: LIGHT BLUE | B6: Estimated input
A7: LIGHT YELLOW | B7: Sourced input (Stripe pricing, Spanish tax law, AWS list)
A8: WHITE | B8: Computed formula
A9: LIGHT GREEN | B9: Dependent value, pulled from another sheet or from the one input at the head of its row
A10: LIGHT GREY | B10: Total or subtotal
A11: LIGHT RED | B11: The balance-sheet check, which must read zero
A13: SHEETS
A14: INPUTS
A15: Assumptions | B15: Every input and assumption taken into consideration
A17: BUILD-UP
A18: Drivers | B18: Athletes and fans, including monthly cohort churn
A19: Revenue | B19: GMV and net revenue, stream by stream
A20: Costs | B20: COGS and operating costs, line by line
A21: WorkingCap | B21: Receivables, payables, athlete float, capex, D&A
A23: THE THREE FINANCIAL STATEMENTS
A24: P&L | B24: Income statement
A25: CashFlow | B25: Cash flow statement, indirect method, tying to closing cash
A26: BalanceSheet | B26: Balance sheet, with an explicit check row so it must balance
A28: VALUATION AND FUNDING
A29: Valuation | B29: DCF, NPV, IRR, exit multiples, sensitivity
A30: Funding | B30: Funding rounds, dilution, ownership shares
A32: OPERATING PLANS
A33: HiringPlan | B33: Headcount by role, at Spanish loaded salaries
A34: CAC_CLV | B34: Acquisition cost against lifetime value
A35: KPIs | B35: Scale, quality of revenue, efficiency
A37: APPENDIX: RESEARCH AND MODELLING
A38: Comparables | B38: Published facts about Patreon, Passes and agents. The benchmarking source
A39: MarketModel | B39: Modelled assumptions, per market dynamics
A40: Research | B40: Where each baseline assumption came from, and how confident it is

Sheet Assumptions
A1: Assumptions
A2: Line | B2: Unit | C2: Y1 | D2: Y2 | E2: Y3 | F2: Y4 | G2: Y5 | H2: Y6 | I2: Y7 | J2: Y8 | K2: Y9 | L2: Y10
A4: MARKET: the plan's shape
A5: Active athletes (year end) | B5: count | C5: 250 | D5: 750 | E5: 1700 | F5: 2800 | G5: 4000 | H5: 5200 | I5: 6300 | J5: 7200 | K5: 7900 | L5: 8500
A6: Niche share of athletes | B6: % | C6: 0.95 | D6: 0.92 | E6: 0.8 | F6: 0.68 | G6: 0.58 | H6: 0.5 | I6: 0.45 | J6: 0.43 | K6: 0.42 | L6: 0.41
A7: Athletes needed for full SaaS value | B7: count | C7: 2000 | D7: =C7 -> 2000 | E7: =C7 -> 2000 | F7: =C7 -> 2000 | G7: =C7 -> 2000 | H7: =C7 -> 2000 | I7: =C7 -> 2000 | J7: =C7 -> 2000 | K7: =C7 -> 2000 | L7: =C7 -> 2000 | N7: Below this, sponsor conversion scales with supply, a matching product is worth nothing against an empty directory
A9: SEGMENT: NICHE
A10: Monetising athletes (niche) | B10: % of segment | C10: 0 | D10: 0.32 | E10: 0.37 | F10: 0.41 | G10: 0.44 | H10: 0.46 | I10: 0.48 | J10: 0.49 | K10: 0.5 | L10: 0.5
A11: Paying fans per monetising athlete (niche) | B11: count | C11: 20 | D11: 22 | E11: 25 | F11: 28 | G11: 30 | H11: 32 | I11: 34 | J11: 35 | K11: 36 | L11: 37 | N11: derived on MarketModel from Patreon members-per-creator
A12: Fan ARPU per month (niche) | B12: EUR | C12: 8 | D12: 8.3 | E12: 8.6 | F12: 8.8 | G12: 9 | H12: 9.1 | I12: 9.2 | J12: 9.3 | K12: 9.4 | L12: 9.5 | N12: derived on MarketModel from our tier mix, cross-checked against Patreon
A13: Fan churn per month (niche) | B13: % | C13: 0.09 | D13: 0.085 | E13: 0.08 | F13: 0.075 | G13: 0.07 | H13: 0.065 | I13: 0.06 | J13: 0.058 | K13: 0.056 | L13: 0.055 | N13: derived on MarketModel from Patreon churn and our annual-plan mix
A14: Athlete churn per year (niche) | B14: % | C14: 0.3 | D14: 0.27 | E14: 0.24 | F14: 0.22 | G14: 0.2 | H14: 0.19 | I14: 0.18 | J14: 0.17 | K14: 0.16 | L14: 0.16
A15: Max new fans per athlete per year (niche) | B15: capacity ceiling | C15: 30 | D15: 33 | E15: 36 | F15: 40 | G15: 43 | H15: 45 | I15: 47 | J15: 49 | K15: 50 | L15: 52 | N15: An audience is finite; without this ceiling higher churn RAISES revenue
A16: Athletes landing a deal (niche) | B16: % of segment | C16: 0.05 | D16: 0.07 | E16: 0.09 | F16: 0.11 | G16: 0.13 | H16: 0.15 | I16: 0.16 | J16: 0.17 | K16: 0.17 | L16: 0.18
A17: Deals per dealing athlete (niche) | B17: count | C17: 1.1 | D17: 1.2 | E17: 1.3 | F17: 1.5 | G17: 1.6 | H17: 1.7 | I17: 1.8 | J17: 1.9 | K17: 1.9 | L17: 2
A18: Average deal value (niche) | B18: EUR | C18: 900 | D18: 1050 | E18: 1200 | F18: 1350 | G18: 1500 | H18: 1600 | I18: 1700 | J18: 1800 | K18: 1900 | L18: 2000
A19: Athlete CAC (niche) | B19: EUR | C19: 16 | D19: 18 | E19: 21 | F19: 24 | G19: 27 | H19: 30 | I19: 32 | J19: 34 | K19: 35 | L19: 36
A21: SEGMENT: POPULAR
A22: Monetising athletes (popular) | B22: % of segment | C22: 0 | D22: 0.17 | E22: 0.2 | F22: 0.23 | G22: 0.26 | H22: 0.28 | I22: 0.3 | J22: 0.31 | K22: 0.32 | L22: 0.32
A23: Paying fans per monetising athlete (popular) | B23: count | C23: 26 | D23: 29 | E23: 32 | F23: 35 | G23: 38 | H23: 41 | I23: 44 | J23: 46 | K23: 47 | L23: 48 | N23: derived on MarketModel from Patreon members-per-creator
A24: Fan ARPU per month (popular) | B24: EUR | C24: 7 | D24: 7.2 | E24: 7.4 | F24: 7.6 | G24: 7.8 | H24: 7.9 | I24: 8 | J24: 8.1 | K24: 8.2 | L24: 8.3 | N24: derived on MarketModel from our tier mix, cross-checked against Patreon
A25: Fan churn per month (popular) | B25: % | C25: 0.13 | D25: 0.125 | E25: 0.12 | F25: 0.11 | G25: 0.105 | H25: 0.1 | I25: 0.09 | J25: 0.088 | K25: 0.086 | L25: 0.085 | N25: derived on MarketModel from Patreon churn and our annual-plan mix
A26: Athlete churn per year (popular) | B26: % | C26: 0.35 | D26: 0.32 | E26: 0.3 | F26: 0.27 | G26: 0.25 | H26: 0.23 | I26: 0.22 | J26: 0.21 | K26: 0.21 | L26: 0.2
A27: Max new fans per athlete per year (popular) | B27: capacity ceiling | C27: 38 | D27: 42 | E27: 46 | F27: 50 | G27: 54 | H27: 58 | I27: 62 | J27: 65 | K27: 67 | L27: 69 | N27: An audience is finite; without this ceiling higher churn RAISES revenue
A28: Athletes landing a deal (popular) | B28: % of segment | C28: 0.14 | D28: 0.17 | E28: 0.2 | F28: 0.24 | G28: 0.27 | H28: 0.29 | I28: 0.3 | J28: 0.31 | K28: 0.31 | L28: 0.32
A29: Deals per dealing athlete (popular) | B29: count | C29: 1.3 | D29: 1.5 | E29: 1.7 | F29: 1.9 | G29: 2.1 | H29: 2.3 | I29: 2.4 | J29: 2.5 | K29: 2.5 | L29: 2.6
A30: Average deal value (popular) | B30: EUR | C30: 2200 | D30: 2500 | E30: 2800 | F30: 3100 | G30: 3400 | H30: 3700 | I30: 4000 | J30: 4200 | K30: 4400 | L30: 4600
A31: Athlete CAC (popular) | B31: EUR | C31: 40 | D31: 46 | E31: 53 | F31: 60 | G31: 67 | H31: 73 | I31: 78 | J31: 82 | K31: 85 | L31: 88
A33: SPONSORS
A34: Registered sponsors | B34: count | C34: 18 | D34: 55 | E34: 125 | F34: 240 | G34: 380 | H34: 510 | I34: 620 | J34: 710 | K34: 790 | L34: 850
A35: Share on a paid plan | B35: % | C35: 0.1 | D35: 0.14 | E35: 0.17 | F35: 0.19 | G35: 0.2 | H35: 0.2 | I35: 0.2 | J35: 0.2 | K35: 0.2 | L35: 0.2
A36: Sponsor plan ARPU per month | B36: EUR | C36: 199 | D36: 229 | E36: 260 | F36: 290 | G36: 320 | H36: 360 | I36: 400 | J36: 430 | K36: 455 | L36: 475
A37: Sponsor CAC | B37: EUR | C37: 900 | D37: 1050 | E37: 1200 | F37: 1400 | G37: 1600 | H37: 1750 | I37: 1900 | J37: 2000 | K37: 2100 | L37: 2200
A39: TAKE RATES & PAYMENT RAILS
A40: Take rate: fan revenue | B40: % | C40: 0.15 | D40: =C40 -> 0.15 | E40: =C40 -> 0.15 | F40: =C40 -> 0.15 | G40: =C40 -> 0.15 | H40: =C40 -> 0.15 | I40: =C40 -> 0.15 | J40: =C40 -> 0.15 | K40: =C40 -> 0.15 | L40: =C40 -> 0.15 | N40: Our pricing decision. OnlyFans/Fansly/Fanfix 20%, Passes 10% + $29/mo
A41: Take rate: sponsorship, base | B41: % | C41: 0.1 | D41: =C41 -> 0.1 | E41: =C41 -> 0.1 | F41: =C41 -> 0.1 | G41: =C41 -> 0.1 | H41: =C41 -> 0.1 | I41: =C41 -> 0.1 | J41: =C41 -> 0.1 | K41: =C41 -> 0.1 | L41: =C41 -> 0.1 | N41: Free and Starter plans. Agents take 10-20% of an endorsement
A42: Take rate: sponsorship, Scout Pro | B42: % | C42: 0.07 | D42: =C42 -> 0.07 | E42: =C42 -> 0.07 | F42: =C42 -> 0.07 | G42: =C42 -> 0.07 | H42: =C42 -> 0.07 | I42: =C42 -> 0.07 | J42: =C42 -> 0.07 | K42: =C42 -> 0.07 | L42: =C42 -> 0.07 | N42: A sponsor paying for the tooling pays less on the deal
A43: Take rate: sponsorship, Scout Agency | B43: % | C43: 0.05 | D43: =C43 -> 0.05 | E43: =C43 -> 0.05 | F43: =C43 -> 0.05 | G43: =C43 -> 0.05 | H43: =C43 -> 0.05 | I43: =C43 -> 0.05 | J43: =C43 -> 0.05 | K43: =C43 -> 0.05 | L43: =C43 -> 0.05 | N43: The most committed tier. Half what an agent charges at the low end
A44: Subscriber deal volume, multiple of average | B44: x | C44: 2 | D44: =C44 -> 2 | E44: =C44 -> 2 | F44: =C44 -> 2 | G44: =C44 -> 2 | H44: =C44 -> 2 | I44: =C44 -> 2 | J44: =C44 -> 2 | K44: =C44 -> 2 | L44: =C44 -> 2 | N44: Subscribers buy campaign capacity, so they run more volume than the average sponsor. The only estimate in the tiering
A45: Scout Starter price | B45: EUR/mo | C45: 99 | D45: =C45 -> 99 | E45: =C45 -> 99 | F45: =C45 -> 99 | G45: =C45 -> 99 | H45: =C45 -> 99 | I45: =C45 -> 99 | J45: =C45 -> 99 | K45: =C45 -> 99 | L45: =C45 -> 99
...

Sheet Drivers
A1: Drivers: Growth Assumptions
A2: Line | B2: Unit | C2: Y1 | D2: Y2 | E2: Y3 | F2: Y4 | G2: Y5 | H2: Y6 | I2: Y7 | J2: Y8 | K2: Y9 | L2: Y10
A4: ATHLETES
A5: Total athletes (year end) | C5: =Assumptions!C5 -> 250 | D5: =Assumptions!D5 -> 750 | E5: =Assumptions!E5 -> 1700 | F5: =Assumptions!F5 -> 2800 | G5: =Assumptions!G5 -> 4000 | H5: =Assumptions!H5 -> 5200 | I5: =Assumptions!I5 -> 6300 | J5: =Assumptions!J5 -> 7200 | ... L5: =Assumptions!L5 -> 8500
A6: Niche athletes | C6: =Drivers!C5*Assumptions!C6 -> 237.5 | D6: =Drivers!D5*Assumptions!D6 -> 690 | E6: =Drivers!E5*Assumptions!E6 -> 1360 | F6: =Drivers!F5*Assumptions!F6 -> 1904 | G6: =Drivers!G5*Assumptions!G6 -> 2320 | H6: =Drivers!H5*Assumptions!H6 -> 2600 | I6: =Drivers!I5*Assumptions!I6 -> 2835 | J6: =Drivers!J5*Assumptions!J6 -> 3096 | ... L6: =Drivers!L5*Assumptions!L6 -> 3485
A7: Popular athletes | C7: =Drivers!C5-Drivers!C6 -> 12.5 | D7: =Drivers!D5-Drivers!D6 -> 60 | E7: =Drivers!E5-Drivers!E6 -> 340 | F7: =Drivers!F5-Drivers!F6 -> 896 | G7: =Drivers!G5-Drivers!G6 -> 1680 | H7: =Drivers!H5-Drivers!H6 -> 2600 | I7: =Drivers!I5-Drivers!I6 -> 3465 | J7: =Drivers!J5-Drivers!J6 -> 4104 | ... L7: =Drivers!L5-Drivers!L6 -> 5015
A9: NICHE: fans and churn
A10: Niche athletes lost to churn | C10: =IF(1=1,0,C6*Assumptions!C14) -> 0 | D10: =IF(2=1,0,C6*Assumptions!D14) -> 64.125 | E10: =IF(3=1,0,D6*Assumptions!E14) -> 165.6 | F10: =IF(4=1,0,E6*Assumptions!F14) -> 299.2 | G10: =IF(5=1,0,F6*Assumptions!G14) -> 380.8 | H10: =IF(6=1,0,G6*Assumptions!H14) -> 440.8 | I10: =IF(7=1,0,H6*Assumptions!I14) -> 468 | J10: =IF(8=1,0,I6*Assumptions!J14) -> 481.95 | K10: =IF(9=1,0,J6*Assumptions!K14) -> 495.36 | L10: =IF(10=1,0,K6*Assumptions!L14) -> 530.88
A11: Niche athletes acquired (gross) | C11: =MAX(0,C6-IF(1=1,0,C6)+C10) -> 237.5 | D11: =MAX(0,D6-IF(2=1,0,C6)+D10) -> 516.625 | E11: =MAX(0,E6-IF(3=1,0,D6)+E10) -> 835.6 | F11: =MAX(0,F6-IF(4=1,0,E6)+F10) -> 843.2 | G11: =MAX(0,G6-IF(5=1,0,F6)+G10) -> 796.8 | H11: =MAX(0,H6-IF(6=1,0,G6)+H10) -> 720.8 | I11: =MAX(0,I6-IF(7=1,0,H6)+I10) -> 703 | J11: =MAX(0,J6-IF(8=1,0,I6)+J10) -> 742.95 | K11: =MAX(0,K6-IF(9=1,0,J6)+K10) -> 717.36 | L11: =MAX(0,L6-IF(10=1,0,K6)+L10) -> 697.88
A12: Niche monetising athletes | C12: =C6*Assumptions!C10 -> 0 | D12: =D6*Assumptions!D10 -> 220.8 | E12: =E6*Assumptions!E10 -> 503.2 | F12: =F6*Assumptions!F10 -> 780.64 | G12: =G6*Assumptions!G10 -> 1020.8 | H12: =H6*Assumptions!H10 -> 1196 | I12: =I6*Assumptions!I10 -> 1360.8 | J12: =J6*Assumptions!J10 -> 1517.04 | ... L12: =L6*Assumptions!L10 -> 1742.5
A13: Niche paying fans (target, year end) | C13: =C12*Assumptions!C11 -> 0 | D13: =D12*Assumptions!D11 -> 4857.6 | E13: =E12*Assumptions!E11 -> 12580 | F13: =F12*Assumptions!F11 -> 21857.92 | G13: =G12*Assumptions!G11 -> 30624 | H13: =H12*Assumptions!H11 -> 38272 | I13: =I12*Assumptions!I11 -> 46267.2 | J13: =J12*Assumptions!J11 -> 53096.4 | ... L13: =L12*Assumptions!L11 -> 64472.5
A14: Niche monthly retention r = 1-churn | B14: factor | C14: =1-Assumptions!C13 -> 0.91 | D14: =1-Assumptions!D13 -> 0.915 | E14: =1-Assumptions!E13 -> 0.92 | F14: =1-Assumptions!F13 -> 0.925 | G14: =1-Assumptions!G13 -> 0.93 | H14: =1-Assumptions!H13 -> 0.935 | I14: =1-Assumptions!I13 -> 0.94 | J14: =1-Assumptions!J13 -> 0.942 | ... L14: =1-Assumptions!L13 -> 0.945
A15: Niche opening fans survived 12 months | B15: open x r^12 | C15: =0 -> 0 | D15: =C17*D14^12 -> 0 | E15: =D17*E14^12 -> 1721.9121 | F15: =E17*F14^12 -> 4936.0714 | G15: =F17*G14^12 -> 9149.6444 | H15: =G17*H14^12 -> 13671.03 | I15: =H17*I14^12 -> 18214.422 | J15: =I17*J14^12 -> 22588.326 | K15: =J17*K14^12 -> 26590.653 | L15: =K17*L14^12 -> 30292.184
A16: Niche monthly gross adds | B16: solved, then capped by capacity | C16: =MIN(MAX(0,(C13-C15)/((1-C14^12)/(1-C14))),C12*Assumptions!C15/12) -> 0 | D16: =MIN(MAX(0,(D13-D15)/((1-D14^12)/(1-D14))),D12*Assumptions!D15/12) -> 607.2 | E16: =MIN(MAX(0,(E13-E15)/((1-E14^12)/(1-E14))),E12*Assumptions!E15/12) -> 1373.7164 | F16: =MIN(MAX(0,(F13-F15)/((1-F14^12)/(1-F14))),F12*Assumptions!F15/12) -> 2088.6857 | G16: =MIN(MAX(0,(G13-G15)/((1-G14^12)/(1-G14))),G12*Assumptions!G15/12) -> 2585.4753 | H16: =MIN(MAX(0,(H13-H15)/((1-H14^12)/(1-H14))),H12*Assumptions!H15/12) -> 2888.5621 | I16: =MIN(MAX(0,(I13-I15)/((1-I14^12)/(1-I14))),I12*Assumptions!I15/12) -> 3211.6617 | J16: =MIN(MAX(0,(J13-J15)/((1-J14^12)/(1-J14))),J12*Assumptions!J15/12) -> 3457.4424 | ... L16: =MIN(MAX(0,(L13-L15)/((1-L14^12)/(1-L14))),L12*Assumptions!L15/12) -> 3814.7896
A17: Niche paying fans (year end) | B17: survivors + capped adds | C17: =C15+C16*(1-C14^12)/(1-C14) -> 0 | D17: =D15+D16*(1-D14^12)/(1-D14) -> 4683.3546 | E17: =E15+E16*(1-E14^12)/(1-E14) -> 12580 | F17: =F15+F16*(1-F14^12)/(1-F14) -> 21857.92 | G17: =G15+G16*(1-G14^12)/(1-G14) -> 30624 | H17: =H15+H16*(1-H14^12)/(1-H14) -> 38272 | I17: =I15+I16*(1-I14^12)/(1-I14) -> 46267.2 | J17: =J15+J16*(1-J14^12)/(1-J14) -> 53096.4 | ... L17: =L15+L16*(1-L14^12)/(1-L14) -> 64472.5
A18: Niche fans acquired (gross) | B18: x12 months | C18: =C16*12 -> 0 | D18: =D16*12 -> 7286.4 | E18: =E16*12 -> 16484.596 | F18: =F16*12 -> 25064.228 | G18: =G16*12 -> 31025.703 | H18: =H16*12 -> 34662.746 | I18: =I16*12 -> 38539.941 | J18: =J16*12 -> 41489.309 | ... L18: =L16*12 -> 45777.475
A19: Niche S = r(1-r^12)/(1-r) | B19: geometric sum | C19: =C14*(1-C14^12)/(1-C14) -> 6.8505256 | D19: =D14*(1-D14^12)/(1-D14) -> 7.0574267 | E19: =E14*(1-E14^12)/(1-E14) -> 7.2718365 | F19: =F14*(1-F14^12)/(1-F14) -> 7.4940476 | G19: =G14*(1-G14^12)/(1-G14) -> 7.7243635 | H19: =H14*(1-H14^12)/(1-H14) -> 7.9630992 | I19: =I14*(1-I14^12)/(1-I14) -> 8.2105817 | J19: =J14*(1-J14^12)/(1-J14) -> 8.3120995 | ... L19: =L14*(1-L14^12)/(1-L14) -> 8.4671507
A20: Niche average fans during year | B20: exact mean, revenue basis | C20: =(C16/(1-C14)*(12-C19))/12 -> 0 | D20: =(C17*D19+D16/(1-D14)*(12-D19))/12 -> 2942.2848 | E20: =(D17*E19+E16/(1-E14)*(12-E19))/12 -> 9603.8361 | F20: =(E17*F19+F16/(1-F14)*(12-F19))/12 -> 18313.502 | G20: =(F17*G19+G16/(1-G14)*(12-G19))/12 -> 27230.058 | H20: =(G17*H19+H16/(1-H14)*(12-H19))/12 -> 35271.623 | I20: =(H17*I19+I16/(1-I14)*(12-I19))/12 -> 43089.518 | J20: =(I17*J19+J16/(1-J14)*(12-J19))/12 -> 50368.107 | K20: =(J17*K19+K16/(1-K14)*(12-K19))/12 -> 57062.63 | L20: =(K17*L19+L16/(1-L14)*(12-L19))/12 -> 62560.822
A21: Niche fans lost to churn | B21: opening + gross adds - closing | C21: =C18-C17 -> 0 | D21: =C17+D18-D17 -> 2603.0454 | E21: =D17+E18-E17 -> 8587.951 | F21: =E17+F18-F17 -> 15786.308 | G21: =F17+G18-G17 -> 22259.623 | H21: =G17+H18-H17 -> 27014.746 | I21: =H17+I18-I17 -> 30544.741 | J21: =I17+J18-J17 -> 34660.109 | K21: =J17+K18-K17 -> 37974.942 | L21: =K17+L18-L17 -> 41028.975
A23: POPULAR: fans and churn
A24: Popular athletes lost to churn | C24: =IF(1=1,0,C7*Assumptions!C26) -> 0 | D24: =IF(2=1,0,C7*Assumptions!D26) -> 4 | E24: =IF(3=1,0,D7*Assumptions!E26) -> 18 | F24: =IF(4=1,0,E7*Assumptions!F26) -> 91.8 | G24: =IF(5=1,0,F7*Assumptions!G26) -> 224 | H24: =IF(6=1,0,G7*Assumptions!H26) -> 386.4 | I24: =IF(7=1,0,H7*Assumptions!I26) -> 572 | J24: =IF(8=1,0,I7*Assumptions!J26) -> 727.65 | K24: =IF(9=1,0,J7*Assumptions!K26) -> 861.84 | L24: =IF(10=1,0,K7*Assumptions!L26) -> 916.4
A25: Popular athletes acquired (gross) | C25: =MAX(0,C7-IF(1=1,0,C7)+C24) -> 12.5 | D25: =MAX(0,D7-IF(2=1,0,C7)+D24) -> 51.5 | E25: =MAX(0,E7-IF(3=1,0,D7)+E24) -> 298 | F25: =MAX(0,F7-IF(4=1,0,E7)+F24) -> 647.8 | G25: =MAX(0,G7-IF(5=1,0,F7)+G24) -> 1008 | H25: =MAX(0,H7-IF(6=1,0,G7)+H24) -> 1306.4 | I25: =MAX(0,I7-IF(7=1,0,H7)+I24) -> 1437 | J25: =MAX(0,J7-IF(8=1,0,I7)+J24) -> 1366.65 | K25: =MAX(0,K7-IF(9=1,0,J7)+K24) -> 1339.84 | L25: =MAX(0,L7-IF(10=1,0,K7)+L24) -> 1349.4
A26: Popular monetising athletes | C26: =C7*Assumptions!C22 -> 0 | D26: =D7*Assumptions!D22 -> 10.2 | E26: =E7*Assumptions!E22 -> 68 | F26: =F7*Assumptions!F22 -> 206.08 | G26: =G7*Assumptions!G22 -> 436.8 | H26: =H7*Assumptions!H22 -> 728 | I26: =I7*Assumptions!I22 -> 1039.5 | J26: =J7*Assumptions!J22 -> 1272.24 | ... L26: =L7*Assumptions!L22 -> 1604.8
A27: Popular paying fans (target, year end) | C27: =C26*Assumptions!C23 -> 0 | D27: =D26*Assumptions!D23 -> 295.8 | E27: =E26*Assumptions!E23 -> 2176 | F27: =F26*Assumptions!F23 -> 7212.8 | G27: =G26*Assumptions!G23 -> 16598.4 | H27: =H26*Assumptions!H23 -> 29848 | I27: =I26*Assumptions!I23 -> 45738 | J27: =J26*Assumptions!J23 -> 58523.04 | ... L27: =L26*Assumptions!L23 -> 77030.4
A28: Popular monthly retention r = 1-churn | B28: factor | C28: =1-Assumptions!C25 -> 0.87 | D28: =1-Assumptions!D25 -> 0.875 | E28: =1-Assumptions!E25 -> 0.88 | F28: =1-Assumptions!F25 -> 0.89 | G28: =1-Assumptions!G25 -> 0.895 | H28: =1-Assumptions!H25 -> 0.9 | I28: =1-Assumptions!I25 -> 0.91 | J28: =1-Assumptions!J25 -> 0.912 | ... L28: =1-Assumptions!L25 -> 0.915
A29: Popular opening fans survived 12 months | B29: open x r^12 | C29: =0 -> 0 | D29: =C31*D28^12 -> 0 | E29: =D31*E28^12 -> 49.18925 | F29: =E31*F28^12 -> 432.95585 | G29: =F31*G28^12 -> 1667.1482 | H29: =G31*H28^12 -> 4361.2674 | I29: =H31*I28^12 -> 9548.5573 | J29: =I31*J28^12 -> 15143.115 | K29: =J31*K28^12 -> 19892.127 | L29: =K31*L28^12 -> 23733.186
A30: Popular monthly gross adds | B30: solved, then capped by capacity | C30: =MIN(MAX(0,(C27-C29)/((1-C28^12)/(1-C28))),C26*Assumptions!C27/12) -> 0 | D30: =MIN(MAX(0,(D27-D29)/((1-D28^12)/(1-D28))),D26*Assumptions!D27/12) -> 35.7 | E30: =MIN(MAX(0,(E27-E29)/((1-E28^12)/(1-E28))),E26*Assumptions!E27/12) -> 260.66667 | F30: =MIN(MAX(0,(F27-F29)/((1-F28^12)/(1-F28))),F26*Assumptions!F27/12) -> 858.66667 | G30: =MIN(MAX(0,(G27-G29)/((1-G28^12)/(1-G28))),G26*Assumptions!G27/12) -> 1965.6 | H30: =MIN(MAX(0,(H27-H29)/((1-H28^12)/(1-H28))),H26*Assumptions!H27/12) -> 3518.6667 | I30: =MIN(MAX(0,(I27-I29)/((1-I28^12)/(1-I28))),I26*Assumptions!I27/12) -> 4807.2797 | J30: =MIN(MAX(0,(J27-J29)/((1-J28^12)/(1-J28))),J26*Assumptions!J27/12) -> 5706.8941 | ... L30: =MIN(MAX(0,(L27-L29)/((1-L28^12)/(1-L28))),L26*Assumptions!L27/12) -> 6910.0187
A31: Popular paying fans (year end) | B31: survivors + capped adds | C31: =C29+C30*(1-C28^12)/(1-C28) -> 0 | D31: =D29+D30*(1-D28^12)/(1-D28) -> 228.07524 | E31: =E29+E30*(1-E28^12)/(1-E28) -> 1752.9258 | F31: =F29+F30*(1-F28^12)/(1-F28) -> 6310.9944 | G31: =G29+G30*(1-G28^12)/(1-G28) -> 15441.966 | H31: =H29+H30*(1-H28^12)/(1-H28) -> 29610.18 | I31: =I29+I30*(1-I28^12)/(1-I28) -> 45738 | J31: =J29+J30*(1-J28^12)/(1-J28) -> 58523.04 | ... L31: =L29+L30*(1-L28^12)/(1-L28) -> 77030.4
A32: Popular fans acquired (gross) | B32: x12 months | C32: =C30*12 -> 0 | D32: =D30*12 -> 428.4 | E32: =E30*12 -> 3128 | F32: =F30*12 -> 10304 | G32: =G30*12 -> 23587.2 | H32: =H30*12 -> 42224 | I32: =I30*12 -> 57687.357 | J32: =J30*12 -> 68482.729 | ... L32: =L30*12 -> 82920.225
A33: Popular S = r(1-r^12)/(1-r) | B33: geometric sum | C33: =C28*(1-C28^12)/(1-C28) -> 5.4339418 | D33: =D28*(1-D28^12)/(1-D28) -> 5.5900793 | E33: =E28*(1-E28^12)/(1-E28) -> 5.7517449 | F33: =F28*(1-F28^12)/(1-F28) -> 6.0925322 | G33: =G28*(1-G28^12)/(1-G28) -> 6.2721114 | H33: =H28*(1-H28^12)/(1-H28) -> 6.4581342 | I33: =I28*(1-I28^12)/(1-I28) -> 6.8505256 | J33: =J28*(1-J28^12)/(1-J28) -> 6.9324032 | ... L33: =L28*(1-L28^12)/(1-L28) -> 7.0574267
A34: Popular average fans during year | B34: exact mean, revenue basis | C34: =(C30/(1-C28)*(12-C33))/12 -> 0 | D34: =(C31*D33+D30/(1-D28)*(12-D33))/12 -> 152.55611 | E34: =(D31*E33+E30/(1-E28)*(12-E33))/12 -> 1240.3691 | F34: =(E31*F33+F30/(1-F28)*(12-F33))/12 -> 4732.8174 | G34: =(F31*G33+G30/(1-G28)*(12-G33))/12 -> 12234.111 | H34: =(G31*H33+H30/(1-H28)*(12-H33))/12 -> 24560.506 | I34: =(H31*I33+I30/(1-I28)*(12-I33))/12 -> 39825.037 | J34: =(I31*J33+J30/(1-J28)*(12-J33))/12 -> 53809.444 | K34: =(J31*K33+K30/(1-K28)*(12-K33))/12 -> 65061.294 | L34: =(K31*L33+L30/(1-L28)*(12-L33))/12 -> 74012.804
A35: Popular fans lost to churn | B35: opening + gross adds - closing | C35: =C32-C31 -> 0 | D35: =C31+D32-D31 -> 200.32476 | E35: =D31+E32-E31 -> 1603.1494 | F35: =E31+F32-F31 -> 5745.9314 | G35: =F31+G32-G31 -> 14456.228 | H35: =G31+H32-H31 -> 28055.786 | I35: =H31+I32-I31 -> 41559.537 | J35: =I31+J32-J31 -> 55697.689 | K35: =J31+K32-K31 -> 66249.694 | L35: =K31+L32-L31 -> 74803.105
A37: TOTALS
A38: Paying fans (year end) | C38: =C17+C31 -> 0 | D38: =D17+D31 -> 4911.4298 | E38: =E17+E31 -> 14332.926 | F38: =F17+F31 -> 28168.914 | G38: =G17+G31 -> 46065.966 | H38: =H17+H31 -> 67882.18 | I38: =I17+I31 -> 92005.2 | J38: =J17+J31 -> 111619.44 | ... L38: =L17+L31 -> 141502.9
A39: Average paying fans | C39: =C20+C34 -> 0 | D39: =D20+D34 -> 3094.8409 | E39: =E20+E34 -> 10844.205 | F39: =F20+F34 -> 23046.32 | G39: =G20+G34 -> 39464.169 | H39: =H20+H34 -> 59832.129 | I39: =I20+I34 -> 82914.555 | J39: =J20+J34 -> 104177.55 | ... L39: =L20+L34 -> 136573.63
A40: Athletes acquired (gross) | C40: =C11+C25 -> 250 | D40: =D11+D25 -> 568.125 | E40: =E11+E25 -> 1133.6 | F40: =F11+F25 -> 1491 | G40: =G11+G25 -> 1804.8 | H40: =H11+H25 -> 2027.2 | I40: =I11+I25 -> 2140 | J40: =J11+J25 -> 2109.6 | ... L40: =L11+L25 -> 2047.28
A41: Fans lost to churn | C41: =C21+C35 -> 0 | D41: =D21+D35 -> 2803.3702 | E41: =E21+E35 -> 10191.1 | F41: =F21+F35 -> 21532.239 | G41: =G21+G35 -> 36715.851 | H41: =H21+H35 -> 55070.532 | I41: =I21+I35 -> 72104.277 | J41: =J21+J35 -> 90357.799 | ... L41: =L21+L35 -> 115832.08
A43: DEALS
A44: Niche deals | C44: =C6*Assumptions!C16*Assumptions!C17 -> 13.0625 | D44: =D6*Assumptions!D16*Assumptions!D17 -> 57.96 | E44: =E6*Assumptions!E16*Assumptions!E17 -> 159.12 | F44: =F6*Assumptions!F16*Assumptions!F17 -> 314.16 | G44: =G6*Assumptions!G16*Assumptions!G17 -> 482.56 | H44: =H6*Assumptions!H16*Assumptions!H17 -> 663 | I44: =I6*Assumptions!I16*Assumptions!I17 -> 816.48 | J44: =J6*Assumptions!J16*Assumptions!J17 -> 1000.008 | ... L44: =L6*Assumptions!L16*Assumptions!L17 -> 1254.6
A45: Popular deals | C45: =C7*Assumptions!C28*Assumptions!C29 -> 2.275 | D45: =D7*Assumptions!D28*Assumptions!D29 -> 15.3 | E45: =E7*Assumptions!E28*Assumptions!E29 -> 115.6 | F45: =F7*Assumptions!F28*Assumptions!F29 -> 408.576 | G45: =G7*Assumptions!G28*Assumptions!G29 -> 952.56 | H45: =H7*Assumptions!H28*Assumptions!H29 -> 1734.2 | I45: =I7*Assumptions!I28*Assumptions!I29 -> 2494.8 | J45: =J7*Assumptions!J28*Assumptions!J29 -> 3180.6 | ... L45: =L7*Assumptions!L28*Assumptions!L29 -> 4172.48
...

Sheet Revenue
A1: Revenue: Stream by stream breakdown
A2: Line | B2: Unit | C2: Y1 | D2: Y2 | E2: Y3 | F2: Y4 | G2: Y5 | H2: Y6 | I2: Y7 | J2: Y8 | K2: Y9 | L2: Y10
A4: FAN GMV: what fans pay athletes, net of VAT
A5: Niche subscription GMV | B5: avg fans x ARPU x 12, ex-VAT | C5: =Drivers!C20*Assumptions!C12*12/(1+Assumptions!C48) -> 0 | D5: =Drivers!D20*Assumptions!D12*12/(1+Assumptions!D48) -> 242191.38 | E5: =Drivers!E20*Assumptions!E12*12/(1+Assumptions!E48) -> 819104.04 | F5: =Drivers!F20*Assumptions!F12*12/(1+Assumptions!F48) -> 1598269.3 | G5: =Drivers!G20*Assumptions!G12*12/(1+Assumptions!G48) -> 2430451.5 | H5: =Drivers!H20*Assumptions!H12*12/(1+Assumptions!H48) -> 3183191.1 | I5: =Drivers!I20*Assumptions!I12*12/(1+Assumptions!I48) -> 3931473.3 | J5: =Drivers!J20*Assumptions!J12*12/(1+Assumptions!J48) -> 4645521.3 | ... L5: =Drivers!L20*Assumptions!L12*12/(1+Assumptions!L48) -> 5894160.1
A6: Popular subscription GMV | B6: ex-VAT | C6: =Drivers!C34*Assumptions!C24*12/(1+Assumptions!C48) -> 0 | D6: =Drivers!D34*Assumptions!D24*12/(1+Assumptions!D48) -> 10893.263 | E6: =Drivers!E34*Assumptions!E24*12/(1+Assumptions!E48) -> 91028.741 | F6: =Drivers!F34*Assumptions!F24*12/(1+Assumptions!F48) -> 356721.44 | G6: =Drivers!G34*Assumptions!G24*12/(1+Assumptions!G48) -> 946374.22 | H6: =Drivers!H34*Assumptions!H24*12/(1+Assumptions!H48) -> 1924244.6 | I6: =Drivers!I34*Assumptions!I24*12/(1+Assumptions!I48) -> 3159672.4 | J6: =Drivers!J34*Assumptions!J24*12/(1+Assumptions!J48) -> 4322543.8 | ... L6: =Drivers!L34*Assumptions!L24*12/(1+Assumptions!L48) -> 6092293.6
A7: Subscription GMV | C7: =C5+C6 -> 0 | D7: =D5+D6 -> 253084.64 | E7: =E5+E6 -> 910132.78 | F7: =F5+F6 -> 1954990.7 | G7: =G5+G6 -> 3376825.7 | H7: =H5+H6 -> 5107435.7 | I7: =I5+I6 -> 7091145.7 | J7: =J5+J6 -> 8968065.1 | ... L7: =L5+L6 -> 11986454
A8: PPV and tips GMV | B8: x multiple | C8: =C7*Assumptions!C49 -> 0 | D8: =D7*Assumptions!D49 -> 88579.625 | E8: =E7*Assumptions!E49 -> 318546.47 | F8: =F7*Assumptions!F49 -> 684246.76 | G8: =G7*Assumptions!G49 -> 1181889 | H8: =H7*Assumptions!H49 -> 1787602.5 | I8: =I7*Assumptions!I49 -> 2481901 | J8: =J7*Assumptions!J49 -> 3138822.8 | ... L8: =L7*Assumptions!L49 -> 4195258.8
A9: Total fan GMV | B9: ex-VAT, the take base | C9: =C7+C8 -> 0 | D9: =D7+D8 -> 341664.27 | E9: =E7+E8 -> 1228679.3 | F9: =F7+F8 -> 2639237.5 | G9: =G7+G8 -> 4558714.7 | H9: =H7+H8 -> 6895038.2 | I9: =I7+I8 -> 9573046.7 | J9: =J7+J8 -> 12106888 | ... L9: =L7+L8 -> 16181713
A10: Fan GMV including VAT | B10: what cards are charged | C10: =C9*(1+Assumptions!C48) -> 0 | D10: =D9*(1+Assumptions!D48) -> 413413.76 | E10: =E9*(1+Assumptions!E48) -> 1486701.9 | F10: =F9*(1+Assumptions!F48) -> 3193477.4 | G10: =G9*(1+Assumptions!G48) -> 5516044.8 | H10: =H9*(1+Assumptions!H48) -> 8342996.2 | I10: =I9*(1+Assumptions!I48) -> 11583387 | J10: =J9*(1+Assumptions!J48) -> 14649334 | ... L10: =L9*(1+Assumptions!L48) -> 19579872
A12: SPONSORSHIP GMV: what sponsors pay athletes and clubs
A13: Niche sponsorship GMV | C13: =Drivers!C44*Assumptions!C18 -> 11756.25 | D13: =Drivers!D44*Assumptions!D18 -> 60858 | E13: =Drivers!E44*Assumptions!E18 -> 190944 | F13: =Drivers!F44*Assumptions!F18 -> 424116 | G13: =Drivers!G44*Assumptions!G18 -> 723840 | H13: =Drivers!H44*Assumptions!H18 -> 1060800 | I13: =Drivers!I44*Assumptions!I18 -> 1388016 | J13: =Drivers!J44*Assumptions!J18 -> 1800014.4 | ... L13: =Drivers!L44*Assumptions!L18 -> 2509200
A14: Popular sponsorship GMV | C14: =Drivers!C45*Assumptions!C30 -> 5005 | D14: =Drivers!D45*Assumptions!D30 -> 38250 | E14: =Drivers!E45*Assumptions!E30 -> 323680 | F14: =Drivers!F45*Assumptions!F30 -> 1266585.6 | G14: =Drivers!G45*Assumptions!G30 -> 3238704 | H14: =Drivers!H45*Assumptions!H30 -> 6416540 | I14: =Drivers!I45*Assumptions!I30 -> 9979200 | J14: =Drivers!J45*Assumptions!J30 -> 13358520 | ... L14: =Drivers!L45*Assumptions!L30 -> 19193408
A15: Total sponsorship GMV | C15: =C13+C14 -> 16761.25 | D15: =D13+D14 -> 99108 | E15: =E13+E14 -> 514624 | F15: =F13+F14 -> 1690701.6 | G15: =G13+G14 -> 3962544 | H15: =H13+H14 -> 7477340 | I15: =I13+I14 -> 11367216 | J15: =J13+J14 -> 15158534 | ... L15: =L13+L14 -> 21702608
A16: Agency share of subscribers | C16: =MAX(0,(Assumptions!C36-Assumptions!C46)/(Assumptions!C47-Assumptions!C46)) -> 0 | D16: =MAX(0,(Assumptions!D36-Assumptions!D46)/(Assumptions!D47-Assumptions!D46)) -> 0 | E16: =MAX(0,(Assumptions!E36-Assumptions!E46)/(Assumptions!E47-Assumptions!E46)) -> 0.014666667 | F16: =MAX(0,(Assumptions!F36-Assumptions!F46)/(Assumptions!F47-Assumptions!F46)) -> 0.054666667 | G16: =MAX(0,(Assumptions!G36-Assumptions!G46)/(Assumptions!G47-Assumptions!G46)) -> 0.094666667 | H16: =MAX(0,(Assumptions!H36-Assumptions!H46)/(Assumptions!H47-Assumptions!H46)) -> 0.148 | I16: =MAX(0,(Assumptions!I36-Assumptions!I46)/(Assumptions!I47-Assumptions!I46)) -> 0.20133333 | J16: =MAX(0,(Assumptions!J36-Assumptions!J46)/(Assumptions!J47-Assumptions!J46)) -> 0.24133333 | ... L16: =MAX(0,(Assumptions!L36-Assumptions!L46)/(Assumptions!L47-Assumptions!L46)) -> 0.30133333
A17: Starter share of subscribers | C17: =MAX(0,(Assumptions!C46-Assumptions!C36)/(Assumptions!C46-Assumptions!C45)) -> 0.33333333 | D17: =MAX(0,(Assumptions!D46-Assumptions!D36)/(Assumptions!D46-Assumptions!D45)) -> 0.13333333 | E17: =MAX(0,(Assumptions!E46-Assumptions!E36)/(Assumptions!E46-Assumptions!E45)) -> 0 | F17: =MAX(0,(Assumptions!F46-Assumptions!F36)/(Assumptions!F46-Assumptions!F45)) -> 0 | G17: =MAX(0,(Assumptions!G46-Assumptions!G36)/(Assumptions!G46-Assumptions!G45)) -> 0 | H17: =MAX(0,(Assumptions!H46-Assumptions!H36)/(Assumptions!H46-Assumptions!H45)) -> 0 | I17: =MAX(0,(Assumptions!I46-Assumptions!I36)/(Assumptions!I46-Assumptions!I45)) -> 0 | J17: =MAX(0,(Assumptions!J46-Assumptions!J36)/(Assumptions!J46-Assumptions!J45)) -> 0 | ... L17: =MAX(0,(Assumptions!L46-Assumptions!L36)/(Assumptions!L46-Assumptions!L45)) -> 0
A18: Subscriber share of deal volume | C18: =MIN(1,Assumptions!C35*Assumptions!C44) -> 0.2 | D18: =MIN(1,Assumptions!D35*Assumptions!D44) -> 0.28 | E18: =MIN(1,Assumptions!E35*Assumptions!E44) -> 0.34 | F18: =MIN(1,Assumptions!F35*Assumptions!F44) -> 0.38 | G18: =MIN(1,Assumptions!G35*Assumptions!G44) -> 0.4 | H18: =MIN(1,Assumptions!H35*Assumptions!H44) -> 0.4 | I18: =MIN(1,Assumptions!I35*Assumptions!I44) -> 0.4 | J18: =MIN(1,Assumptions!J35*Assumptions!J44) -> 0.4 | ... L18: =MIN(1,Assumptions!L35*Assumptions!L44) -> 0.4
A19: Effective sponsorship take | C19: =(1-C18)*Assumptions!C41+C18*(C17*Assumptions!C41+(1-C17-C16)*Assumptions!C42+C16*Assumptions!C43) -> 0.096 | D19: =(1-D18)*Assumptions!D41+D18*(D17*Assumptions!D41+(1-D17-D16)*Assumptions!D42+D16*Assumptions!D43) -> 0.09272 | E19: =(1-E18)*Assumptions!E41+E18*(E17*Assumptions!E41+(1-E17-E16)*Assumptions!E42+E16*Assumptions!E43) -> 0.089700267 | F19: =(1-F18)*Assumptions!F41+F18*(F17*Assumptions!F41+(1-F17-F16)*Assumptions!F42+F16*Assumptions!F43) -> 0.088184533 | G19: =(1-G18)*Assumptions!G41+G18*(G17*Assumptions!G41+(1-G17-G16)*Assumptions!G42+G16*Assumptions!G43) -> 0.087242667 | H19: =(1-H18)*Assumptions!H41+H18*(H17*Assumptions!H41+(1-H17-H16)*Assumptions!H42+H16*Assumptions!H43) -> 0.086816 | I19: =(1-I18)*Assumptions!I41+I18*(I17*Assumptions!I41+(1-I17-I16)*Assumptions!I42+I16*Assumptions!I43) -> 0.086389333 | J19: =(1-J18)*Assumptions!J41+J18*(J17*Assumptions!J41+(1-J17-J16)*Assumptions!J42+J16*Assumptions!J43) -> 0.086069333 | ... L19: =(1-L18)*Assumptions!L41+L18*(L17*Assumptions!L41+(1-L17-L16)*Assumptions!L42+L16*Assumptions!L43) -> 0.085589333
A20: TOTAL GMV | C20: =C9+C15 -> 16761.25 | D20: =D9+D15 -> 440772.27 | E20: =E9+E15 -> 1743303.3 | F20: =F9+F15 -> 4329939.1 | G20: =G9+G15 -> 8521258.7 | H20: =H9+H15 -> 14372378 | I20: =I9+I15 -> 20940263 | J20: =J9+J15 -> 27265422 | ... L20: =L9+L15 -> 37884321
A22: NET REVENUE: our share
A23: Fan take | B23: fan GMV x take rate | C23: =C9*Assumptions!C40 -> 0 | D23: =D9*Assumptions!D40 -> 51249.64 | E23: =E9*Assumptions!E40 -> 184301.89 | F23: =F9*Assumptions!F40 -> 395885.62 | G23: =G9*Assumptions!G40 -> 683807.2 | H23: =H9*Assumptions!H40 -> 1034255.7 | I23: =I9*Assumptions!I40 -> 1435957 | J23: =J9*Assumptions!J40 -> 1816033.2 | ... L23: =L9*Assumptions!L40 -> 2427256.9
A24: Sponsorship take | C24: =C15*C19 -> 1609.08 | D24: =D15*D19 -> 9189.2938 | E24: =E15*E19 -> 46161.91 | F24: =F15*F19 -> 149093.73 | G24: =G15*G19 -> 345702.91 | H24: =H15*H19 -> 649152.75 | I24: =I15*I19 -> 982006.21 | J24: =J15*J19 -> 1304685 | ... L24: =L15*L19 -> 1857511.8
A25: Sponsor SaaS | B25: paying sponsors x ARPU x 12 | C25: =Drivers!C48*Assumptions!C36*12 -> 537.3 | D25: =Drivers!D48*Assumptions!D36*12 -> 7934.85 | E25: =Drivers!E48*Assumptions!E36*12 -> 56355 | F25: =Drivers!F48*Assumptions!F36*12 -> 158688 | G25: =Drivers!G48*Assumptions!G36*12 -> 291840 | H25: =Drivers!H48*Assumptions!H36*12 -> 440640 | I25: =Drivers!I48*Assumptions!I36*12 -> 595200 | J25: =Drivers!J48*Assumptions!J36*12 -> 732720 | ... L25: =Drivers!L48*Assumptions!L36*12 -> 969000
A26: NET REVENUE | C26: =SUM(C23:C25) -> 2146.38 | D26: =SUM(D23:D25) -> 68373.784 | E26: =SUM(E23:E25) -> 286818.8 | F26: =SUM(F23:F25) -> 703667.36 | G26: =SUM(G23:G25) -> 1321350.1 | H26: =SUM(H23:H25) -> 2124048.5 | I26: =SUM(I23:I25) -> 3013163.2 | J26: =SUM(J23:J25) -> 3853438.1 | ... L26: =SUM(L23:L25) -> 5253768.6
A27: Growth | B27: % YoY | C27: =IF(1=1,"",C26/C26-1) | D27: =IF(2=1,"",D26/C26-1) -> 30.855396 | E27: =IF(3=1,"",E26/D26-1) -> 3.1948651 | F27: =IF(4=1,"",F26/E26-1) -> 1.4533516 | G27: =IF(5=1,"",G26/F26-1) -> 0.87780504 | H27: =IF(6=1,"",H26/G26-1) -> 0.60748349 | I27: =IF(7=1,"",I26/H26-1) -> 0.41859438 | J27: =IF(8=1,"",J26/I26-1) -> 0.27886803 | K27: =IF(9=1,"",K26/J26-1) -> 0.17470552 | L27: =IF(10=1,"",L26/K26-1) -> 0.16062933
A28: Take rate on GMV | B28: blended | C28: =C26/C20 -> 0.12805608 | D28: =D26/D20 -> 0.1551227 | E28: =E26/E20 -> 0.16452605 | F28: =F26/F20 -> 0.16251207 | G28: =G26/G20 -> 0.15506513 | H28: =H26/H20 -> 0.14778685 | I28: =I26/I20 -> 0.14389329 | J28: =J26/J20 -> 0.14133059 | ... L28: =L26/L20 -> 0.13867924

Sheet Costs
A1: Costs
A2: Line | B2: Unit | C2: Y1 | D2: Y2 | E2: Y3 | F2: Y4 | G2: Y5 | H2: Y6 | I2: Y7 | J2: Y8 | K2: Y9 | L2: Y10
A4: COST OF SALES
A5: Fan transactions | B5: fan GMV incl VAT / avg ticket | C5: =Revenue!C10/Assumptions!C54 -> 0 | D5: =Revenue!D10/Assumptions!D54 -> 44936.279 | E5: =Revenue!E10/Assumptions!E54 -> 161598.03 | F5: =Revenue!F10/Assumptions!F54 -> 347117.11 | G5: =Revenue!G10/Assumptions!G54 -> 599570.08 | H5: =Revenue!H10/Assumptions!H54 -> 906847.41 | I5: =Revenue!I10/Assumptions!I54 -> 1259063.8 | J5: =Revenue!J10/Assumptions!J54 -> 1592318.9 | ... L5: =Revenue!L10/Assumptions!L54 -> 2128247
A6: Deal transactions | B6: count | C6: =Revenue!C15/Assumptions!C55 -> 9.3118056 | D6: =Revenue!D15/Assumptions!D55 -> 55.06 | E6: =Revenue!E15/Assumptions!E55 -> 285.90222 | F6: =Revenue!F15/Assumptions!F55 -> 939.27867 | G6: =Revenue!G15/Assumptions!G55 -> 2201.4133 | H6: =Revenue!H15/Assumptions!H55 -> 4154.0778 | I6: =Revenue!I15/Assumptions!I55 -> 6315.12 | J6: =Revenue!J15/Assumptions!J55 -> 8421.408 | ... L6: =Revenue!L15/Assumptions!L55 -> 12057.004
A7: Payment processing | B7: % of processed + fixed | C7: =(Revenue!C10+Revenue!C15)*Assumptions!C50+(C5+C6)*Assumptions!C51 -> 320.7917 | D7: =(Revenue!D10+Revenue!D15)*Assumptions!D50+(D5+D6)*Assumptions!D51 -> 20985.748 | E7: =(Revenue!E10+Revenue!E15)*Assumptions!E50+(E5+E6)*Assumptions!E51 -> 78496.176 | F7: =(Revenue!F10+Revenue!F15)*Assumptions!F50+(F5+F6)*Assumptions!F51 -> 179813.5 | G7: =(Revenue!G10+Revenue!G15)*Assumptions!G50+(G5+G6)*Assumptions!G51 -> 330536.06 | H7: =(Revenue!H10+Revenue!H15)*Assumptions!H50+(H5+H6)*Assumptions!H51 -> 528336.76 | I7: =(Revenue!I10+Revenue!I15)*Assumptions!I50+(I5+I6)*Assumptions!I51 -> 752406.17 | J7: =(Revenue!J10+Revenue!J15)*Assumptions!J50+(J5+J6)*Assumptions!J51 -> 966534.59 | ... L7: =(Revenue!L10+Revenue!L15)*Assumptions!L50+(L5+L6)*Assumptions!L51 -> 1319443.1
A8: Payouts to athletes | B8: % + fixed | C8: =(Revenue!C10+Revenue!C15)*Assumptions!C52+(C5/30+C6)*Assumptions!C53 -> 44.231076 | D8: =(Revenue!D10+Revenue!D15)*Assumptions!D52+(D5/30+D6)*Assumptions!D53 -> 1669.5384 | E8: =(Revenue!E10+Revenue!E15)*Assumptions!E52+(E5/30+E6)*Assumptions!E53 -> 6421.4406 | F8: =(Revenue!F10+Revenue!F15)*Assumptions!F52+(F5/30+F6)*Assumptions!F53 -> 15337.91 | G8: =(Revenue!G10+Revenue!G15)*Assumptions!G52+(G5/30+G6)*Assumptions!G53 -> 29243.243 | H8: =(Revenue!H10+Revenue!H15)*Assumptions!H52+(H5/30+H6)*Assumptions!H53 -> 48146.422 | I8: =(Revenue!I10+Revenue!I15)*Assumptions!I52+(I5/30+I6)*Assumptions!I53 -> 69447.484 | J8: =(Revenue!J10+Revenue!J15)*Assumptions!J52+(J5/30+J6)*Assumptions!J53 -> 89894.348 | ... L8: =(Revenue!L10+Revenue!L15)*Assumptions!L52+(L5/30+L6)*Assumptions!L53 -> 123955.84
A9: Media egress GB | B9: GB/yr | C9: =Drivers!C39*Assumptions!C59*12 -> 0 | D9: =Drivers!D39*Assumptions!D59*12 -> 66848.564 | E9: =Drivers!E39*Assumptions!E59*12 -> 234234.83 | F9: =Drivers!F39*Assumptions!F59*12 -> 497800.51 | G9: =Drivers!G39*Assumptions!G59*12 -> 852426.06 | H9: =Drivers!H39*Assumptions!H59*12 -> 1292374 | I9: =Drivers!I39*Assumptions!I59*12 -> 1790954.4 | J9: =Drivers!J39*Assumptions!J59*12 -> 2250235.1 | ... L9: =Drivers!L39*Assumptions!L59*12 -> 2949990.3
A10: Infrastructure (AWS + CDN) | B10: base + egress | C10: =Assumptions!C58*12+C9*Assumptions!C60 -> 1800 | D10: =Assumptions!D58*12+D9*Assumptions!D60 -> 5574.7885 | E10: =Assumptions!E58*12+E9*Assumptions!E60 -> 13873.879 | F10: =Assumptions!F58*12+F9*Assumptions!F60 -> 27982.404 | G10: =Assumptions!G58*12+G9*Assumptions!G60 -> 45219.408 | H10: =Assumptions!H58*12+H9*Assumptions!H60 -> 61938.992 | I10: =Assumptions!I58*12+I9*Assumptions!I60 -> 77927.635 | J10: =Assumptions!J58*12+J9*Assumptions!J60 -> 92401.881 | ... L10: =Assumptions!L58*12+L9*Assumptions!L60 -> 117199.92
A11: memo: same egress at CloudFront list | B11: the trap | C11: =Assumptions!C58*12+C9*Assumptions!C61 -> 1800 | D11: =Assumptions!D58*12+D9*Assumptions!D61 -> 10053.642 | E11: =Assumptions!E58*12+E9*Assumptions!E61 -> 29567.612 | F11: =Assumptions!F58*12+F9*Assumptions!F61 -> 61335.038 | G11: =Assumptions!G58*12+G9*Assumptions!G61 -> 102331.95 | H11: =Assumptions!H58*12+H9*Assumptions!H61 -> 148528.05 | I11: =Assumptions!I58*12+I9*Assumptions!I61 -> 197921.58 | J11: =Assumptions!J58*12+J9*Assumptions!J61 -> 243167.63 | ... L11: =Assumptions!L58*12+L9*Assumptions!L61 -> 314849.27
A12: Moderation | B12: items x rate | C12: =Drivers!C5*Assumptions!C63*12/1000*Assumptions!C62 -> 792 | D12: =Drivers!D5*Assumptions!D63*12/1000*Assumptions!D62 -> 2376 | E12: =Drivers!E5*Assumptions!E63*12/1000*Assumptions!E62 -> 5385.6 | F12: =Drivers!F5*Assumptions!F63*12/1000*Assumptions!F62 -> 8870.4 | G12: =Drivers!G5*Assumptions!G63*12/1000*Assumptions!G62 -> 12672 | H12: =Drivers!H5*Assumptions!H63*12/1000*Assumptions!H62 -> 16473.6 | I12: =Drivers!I5*Assumptions!I63*12/1000*Assumptions!I62 -> 19958.4 | J12: =Drivers!J5*Assumptions!J63*12/1000*Assumptions!J62 -> 22809.6 | ... L12: =Drivers!L5*Assumptions!L63*12/1000*Assumptions!L62 -> 26928
A13: Athlete verification | B13: reviews x minutes x hourly | C13: =Drivers!C55*Assumptions!C103/60*(Assumptions!C67/Assumptions!C104) -> 465.68627 | D13: =Drivers!D55*Assumptions!D103/60*(Assumptions!D67/Assumptions!D104) -> 1251.2118 | E13: =Drivers!E55*Assumptions!E103/60*(Assumptions!E67/Assumptions!E104) -> 2517.9256 | F13: =Drivers!F55*Assumptions!F103/60*(Assumptions!F67/Assumptions!F104) -> 3193.2737 | G13: =Drivers!G55*Assumptions!G103/60*(Assumptions!G67/Assumptions!G104) -> 3707.495 | H13: =Drivers!H55*Assumptions!H103/60*(Assumptions!H67/Assumptions!H104) -> 4093.7987 | I13: =Drivers!I55*Assumptions!I103/60*(Assumptions!I67/Assumptions!I104) -> 4248.9077 | J13: =Drivers!J55*Assumptions!J103/60*(Assumptions!J67/Assumptions!J104) -> 4211.8344 | ... L13: =Drivers!L55*Assumptions!L103/60*(Assumptions!L67/Assumptions!L104) -> 4172.2157
A14: TOTAL COST OF SALES | C14: =C7+C8+C10+C12+C13 -> 3422.7091 | D14: =D7+D8+D10+D12+D13 -> 31857.287 | E14: =E7+E8+E10+E12+E13 -> 106695.02 | F14: =F7+F8+F10+F12+F13 -> 235197.48 | G14: =G7+G8+G10+G12+G13 -> 421378.21 | H14: =H7+H8+H10+H12+H13 -> 658989.57 | I14: =I7+I8+I10+I12+I13 -> 923988.59 | J14: =J7+J8+J10+J12+J13 -> 1175852.3 | ... L14: =L7+L8+L10+L12+L13 -> 1591699.1
A16: OPERATING COSTS
A17: People | B17: FTE x loaded salary | C17: =Assumptions!C66*Assumptions!C67 -> 38000 | D17: =Assumptions!D66*Assumptions!D67 -> 78000 | E17: =Assumptions!E66*Assumptions!E67 -> 90000 | F17: =Assumptions!F66*Assumptions!F67 -> 128000 | G17: =Assumptions!G66*Assumptions!G67 -> 264000 | H17: =Assumptions!H66*Assumptions!H67 -> 476000 | I17: =Assumptions!I66*Assumptions!I67 -> 700000 | J17: =Assumptions!J66*Assumptions!J67 -> 900000 | ... L17: =Assumptions!L66*Assumptions!L67 -> 1216000
A18: Athlete acquisition: niche | B18: gross adds x CAC | C18: =Drivers!C11*Assumptions!C19 -> 3800 | D18: =Drivers!D11*Assumptions!D19 -> 9299.25 | E18: =Drivers!E11*Assumptions!E19 -> 17547.6 | F18: =Drivers!F11*Assumptions!F19 -> 20236.8 | G18: =Drivers!G11*Assumptions!G19 -> 21513.6 | H18: =Drivers!H11*Assumptions!H19 -> 21624 | I18: =Drivers!I11*Assumptions!I19 -> 22496 | J18: =Drivers!J11*Assumptions!J19 -> 25260.3 | ... L18: =Drivers!L11*Assumptions!L19 -> 25123.68
A19: Athlete acquisition: popular | C19: =Drivers!C25*Assumptions!C31 -> 500 | D19: =Drivers!D25*Assumptions!D31 -> 2369 | E19: =Drivers!E25*Assumptions!E31 -> 15794 | F19: =Drivers!F25*Assumptions!F31 -> 38868 | G19: =Drivers!G25*Assumptions!G31 -> 67536 | H19: =Drivers!H25*Assumptions!H31 -> 95367.2 | I19: =Drivers!I25*Assumptions!I31 -> 112086 | J19: =Drivers!J25*Assumptions!J31 -> 112065.3 | ... L19: =Drivers!L25*Assumptions!L31 -> 118747.2
A20: Sponsor acquisition | C20: =Drivers!C49*Assumptions!C37 -> 16200 | D20: =Drivers!D49*Assumptions!D37 -> 38850 | E20: =Drivers!E49*Assumptions!E37 -> 84000 | F20: =Drivers!F49*Assumptions!F37 -> 161000 | G20: =Drivers!G49*Assumptions!G37 -> 224000 | H20: =Drivers!H49*Assumptions!H37 -> 227500 | I20: =Drivers!I49*Assumptions!I37 -> 209000 | J20: =Drivers!J49*Assumptions!J37 -> 180000 | ... L20: =Drivers!L49*Assumptions!L37 -> 132000
A21: Total marketing / CAC | C21: =SUM(C18:C20) -> 20500 | D21: =SUM(D18:D20) -> 50518.25 | E21: =SUM(E18:E20) -> 117341.6 | F21: =SUM(F18:F20) -> 220104.8 | G21: =SUM(G18:G20) -> 313049.6 | H21: =SUM(H18:H20) -> 344491.2 | I21: =SUM(I18:I20) -> 343582 | J21: =SUM(J18:J20) -> 317325.6 | ... L21: =SUM(L18:L20) -> 275870.88
A22: memo: athlete marketing per application | B22: CAC is per ADMITTED athlete | C22: =(C18+C19)/Drivers!C54 -> 3.44 | D22: =(D18+D19)/Drivers!D54 -> 4.6210891 | E22: =(E18+E19)/Drivers!E54 -> 7.3530346 | F22: =(F18+F19)/Drivers!F54 -> 10.703082 | G22: =(G18+G19)/Drivers!G54 -> 14.062021 | H22: =(H18+H19)/Drivers!H54 -> 17.024667 | I22: =(I18+I19)/Drivers!I54 -> 19.181079 | J22: =(J18+J19)/Drivers!J54 -> 20.179625 | ... L22: =(L18+L19)/Drivers!L54 -> 22.312045
A23: Legal: base | C23: =Assumptions!C69+Assumptions!C70*MAX(0,Assumptions!C66-1) -> 3600 | D23: =Assumptions!D69+Assumptions!D70*MAX(0,Assumptions!D66-1) -> 4050 | E23: =Assumptions!E69+Assumptions!E70*MAX(0,Assumptions!E66-1) -> 4050 | F23: =Assumptions!F69+Assumptions!F70*MAX(0,Assumptions!F66-1) -> 4500 | G23: =Assumptions!G69+Assumptions!G70*MAX(0,Assumptions!G66-1) -> 6300 | H23: =Assumptions!H69+Assumptions!H70*MAX(0,Assumptions!H66-1) -> 9000 | I23: =Assumptions!I69+Assumptions!I70*MAX(0,Assumptions!I66-1) -> 11700 | J23: =Assumptions!J69+Assumptions!J70*MAX(0,Assumptions!J66-1) -> 13950 | ... L23: =Assumptions!L69+Assumptions!L70*MAX(0,Assumptions!L66-1) -> 17100
A24: Legal: incorporation and launch pack | C24: =IF(1=1,Assumptions!C71+Assumptions!C72,0) -> 10500 | D24: =IF(2=1,Assumptions!D71+Assumptions!D72,0) -> 0 | E24: =IF(3=1,Assumptions!E71+Assumptions!E72,0) -> 0 | F24: =IF(4=1,Assumptions!F71+Assumptions!F72,0) -> 0 | G24: =IF(5=1,Assumptions!G71+Assumptions!G72,0) -> 0 | H24: =IF(6=1,Assumptions!H71+Assumptions!H72,0) -> 0 | I24: =IF(7=1,Assumptions!I71+Assumptions!I72,0) -> 0 | J24: =IF(8=1,Assumptions!J71+Assumptions!J72,0) -> 0 | K24: =IF(9=1,Assumptions!K71+Assumptions!K72,0) -> 0 | L24: =IF(10=1,Assumptions!L71+Assumptions!L72,0) -> 0
A25: Legal: DAC7 | C25: =IF(1=1,4000,Assumptions!C73) -> 4000 | D25: =IF(2=1,4000,Assumptions!D73) -> 2500 | E25: =IF(3=1,4000,Assumptions!E73) -> 2500 | F25: =IF(4=1,4000,Assumptions!F73) -> 2500 | G25: =IF(5=1,4000,Assumptions!G73) -> 2500 | H25: =IF(6=1,4000,Assumptions!H73) -> 2500 | I25: =IF(7=1,4000,Assumptions!I73) -> 2500 | J25: =IF(8=1,4000,Assumptions!J73) -> 2500 | K25: =IF(9=1,4000,Assumptions!K73) -> 2500 | L25: =IF(10=1,4000,Assumptions!L73) -> 2500
A26: Legal: content and DSA | C26: =Assumptions!C74 -> 0 | D26: =Assumptions!D74 -> 6000 | E26: =Assumptions!E74 -> 5400 | F26: =Assumptions!F74 -> 5800 | G26: =Assumptions!G74 -> 6200 | H26: =Assumptions!H74 -> 6600 | I26: =Assumptions!I74 -> 7000 | J26: =Assumptions!J74 -> 7400 | ... L26: =Assumptions!L74 -> 8200
A27: Legal: market entry | C27: =Assumptions!C75*MAX(0,IF(1=1,Assumptions!C68,Assumptions!C68-Assumptions!C68)) -> 7000 | D27: =Assumptions!D75*MAX(0,IF(2=1,Assumptions!D68,Assumptions!D68-Assumptions!C68)) -> 7000 | E27: =Assumptions!E75*MAX(0,IF(3=1,Assumptions!E68,Assumptions!E68-Assumptions!D68)) -> 0 | F27: =Assumptions!F75*MAX(0,IF(4=1,Assumptions!F68,Assumptions!F68-Assumptions!E68)) -> 0 | G27: =Assumptions!G75*MAX(0,IF(5=1,Assumptions!G68,Assumptions!G68-Assumptions!F68)) -> 7000 | H27: =Assumptions!H75*MAX(0,IF(6=1,Assumptions!H68,Assumptions!H68-Assumptions!G68)) -> 7000 | I27: =Assumptions!I75*MAX(0,IF(7=1,Assumptions!I68,Assumptions!I68-Assumptions!H68)) -> 7000 | J27: =Assumptions!J75*MAX(0,IF(8=1,Assumptions!J68,Assumptions!J68-Assumptions!I68)) -> 7000 | K27: =Assumptions!K75*MAX(0,IF(9=1,Assumptions!K68,Assumptions!K68-Assumptions!J68)) -> 0 | L27: =Assumptions!L75*MAX(0,IF(10=1,Assumptions!L68,Assumptions!L68-Assumptions!K68)) -> 0
A28: Legal: VAT and tax | C28: =Assumptions!C76*Assumptions!C68 -> 2500 | D28: =Assumptions!D76*Assumptions!D68 -> 5000 | E28: =Assumptions!E76*Assumptions!E68 -> 5000 | F28: =Assumptions!F76*Assumptions!F68 -> 5000 | G28: =Assumptions!G76*Assumptions!G68 -> 7500 | H28: =Assumptions!H76*Assumptions!H68 -> 10000 | I28: =Assumptions!I76*Assumptions!I68 -> 12500 | J28: =Assumptions!J76*Assumptions!J68 -> 15000 | ... L28: =Assumptions!L76*Assumptions!L68 -> 15000
A29: Legal: round documentation | C29: =Assumptions!C77 -> 8000 | D29: =Assumptions!D77 -> 10000 | E29: =Assumptions!E77 -> 0 | F29: =Assumptions!F77 -> 0 | G29: =Assumptions!G77 -> 0 | H29: =Assumptions!H77 -> 25000 | I29: =Assumptions!I77 -> 0 | J29: =Assumptions!J77 -> 0 | ... L29: =Assumptions!L77 -> 0
A30: Legal: IP | C30: =Assumptions!C78+Assumptions!C79*MAX(0,IF(1=1,Assumptions!C68,Assumptions!C68-Assumptions!C68)) -> 8000 | D30: =Assumptions!D78+Assumptions!D79*MAX(0,IF(2=1,Assumptions!D68,Assumptions!D68-Assumptions!C68)) -> 3500 | E30: =Assumptions!E78+Assumptions!E79*MAX(0,IF(3=1,Assumptions!E68,Assumptions!E68-Assumptions!D68)) -> 1500 | F30: =Assumptions!F78+Assumptions!F79*MAX(0,IF(4=1,Assumptions!F68,Assumptions!F68-Assumptions!E68)) -> 1500 | G30: =Assumptions!G78+Assumptions!G79*MAX(0,IF(5=1,Assumptions!G68,Assumptions!G68-Assumptions!F68)) -> 3500 | H30: =Assumptions!H78+Assumptions!H79*MAX(0,IF(6=1,Assumptions!H68,Assumptions!H68-Assumptions!G68)) -> 3500 | I30: =Assumptions!I78+Assumptions!I79*MAX(0,IF(7=1,Assumptions!I68,Assumptions!I68-Assumptions!H68)) -> 3500 | J30: =Assumptions!J78+Assumptions!J79*MAX(0,IF(8=1,Assumptions!J68,Assumptions!J68-Assumptions!I68)) -> 3500 | K30: =Assumptions!K78+Assumptions!K79*MAX(0,IF(9=1,Assumptions!K68,Assumptions!K68-Assumptions!J68)) -> 1500 | L30: =Assumptions!L78+Assumptions!L79*MAX(0,IF(10=1,Assumptions!L68,Assumptions!L68-Assumptions!K68)) -> 1500
A31: Legal: employment | C31: =Assumptions!C80*MAX(0,IF(1=1,Assumptions!C66,Assumptions!C66-Assumptions!C66))+IF(Assumptions!C66>=Assumptions!C82,Assumptions!C81,0) -> 500 | D31: =Assumptions!D80*MAX(0,IF(2=1,Assumptions!D66,Assumptions!D66-Assumptions!C66))+IF(Assumptions!D66>=Assumptions!D82,Assumptions!D81,0) -> 250 | E31: =Assumptions!E80*MAX(0,IF(3=1,Assumptions!E66,Assumptions!E66-Assumptions!D66))+IF(Assumptions!E66>=Assumptions!E82,Assumptions!E81,0) -> 0 | F31: =Assumptions!F80*MAX(0,IF(4=1,Assumptions!F66,Assumptions!F66-Assumptions!E66))+IF(Assumptions!F66>=Assumptions!F82,Assumptions!F81,0) -> 250 | G31: =Assumptions!G80*MAX(0,IF(5=1,Assumptions!G66,Assumptions!G66-Assumptions!F66))+IF(Assumptions!G66>=Assumptions!G82,Assumptions!G81,0) -> 2500 | H31: =Assumptions!H80*MAX(0,IF(6=1,Assumptions!H66,Assumptions!H66-Assumptions!G66))+IF(Assumptions!H66>=Assumptions!H82,Assumptions!H81,0) -> 3000 | I31: =Assumptions!I80*MAX(0,IF(7=1,Assumptions!I66,Assumptions!I66-Assumptions!H66))+IF(Assumptions!I66>=Assumptions!I82,Assumptions!I81,0) -> 3000 | J31: =Assumptions!J80*MAX(0,IF(8=1,Assumptions!J66,Assumptions!J66-Assumptions!I66))+IF(Assumptions!J66>=Assumptions!J82,Assumptions!J81,0) -> 2750 | K31: =Assumptions!K80*MAX(0,IF(9=1,Assumptions!K66,Assumptions!K66-Assumptions!J66))+IF(Assumptions!K66>=Assumptions!K82,Assumptions!K81,0) -> 2500 | L31: =Assumptions!L80*MAX(0,IF(10=1,Assumptions!L66,Assumptions!L66-Assumptions!K66))+IF(Assumptions!L66>=Assumptions!L82,Assumptions!L81,0) -> 2250
A32: Legal: disputes | C32: =Assumptions!C83*Revenue!C20 -> 5.028375 | D32: =Assumptions!D83*Revenue!D20 -> 132.23168 | E32: =Assumptions!E83*Revenue!E20 -> 522.99098 | F32: =Assumptions!F83*Revenue!F20 -> 1298.9817 | G32: =Assumptions!G83*Revenue!G20 -> 2556.3776 | H32: =Assumptions!H83*Revenue!H20 -> 4311.7135 | I32: =Assumptions!I83*Revenue!I20 -> 6282.0788 | J32: =Assumptions!J83*Revenue!J20 -> 8179.6267 | ... L32: =Assumptions!L83*Revenue!L20 -> 11365.296
A33: Legal & compliance | C33: =SUM(C23:C32)*(1+Assumptions!C84) -> 50720.783 | D33: =SUM(D23:D32)*(1+Assumptions!D84) -> 44197.066 | E33: =SUM(E23:E32)*(1+Assumptions!E84) -> 21818.94 | F33: =SUM(F23:F32)*(1+Assumptions!F84) -> 23976.329 | G33: =SUM(G23:G32)*(1+Assumptions!G84) -> 43764.834 | H33: =SUM(H23:H32)*(1+Assumptions!H84) -> 81548.47 | I33: =SUM(I23:I32)*(1+Assumptions!I84) -> 61504.391 | J33: =SUM(J23:J32)*(1+Assumptions!J84) -> 69321.571 | ... L33: =SUM(L23:L32)*(1+Assumptions!L84) -> 66602.591
A34: Other opex | B34: % of revenue | C34: =Revenue!C26*Assumptions!C85 -> 171.7104 | D34: =Revenue!D26*Assumptions!D85 -> 5469.9027 | E34: =Revenue!E26*Assumptions!E85 -> 22945.504 | F34: =Revenue!F26*Assumptions!F85 -> 56293.388 | G34: =Revenue!G26*Assumptions!G85 -> 105708.01 | H34: =Revenue!H26*Assumptions!H85 -> 169923.88 | I34: =Revenue!I26*Assumptions!I85 -> 241053.06 | J34: =Revenue!J26*Assumptions!J85 -> 308275.05 | ... L34: =Revenue!L26*Assumptions!L85 -> 420301.49
A35: TOTAL OPERATING COSTS | C35: =C17+C21+C33+C34 -> 109392.49 | D35: =D17+D21+D33+D34 -> 178185.22 | E35: =E17+E21+E33+E34 -> 252106.04 | F35: =F17+F21+F33+F34 -> 428374.52 | G35: =G17+G21+G33+G34 -> 726522.44 | H35: =H17+H21+H33+H34 -> 1071963.5 | I35: =I17+I21+I33+I34 -> 1346139.4 | J35: =J17+J21+J33+J34 -> 1594922.2 | ... L35: =L17+L21+L33+L34 -> 1978775

Sheet WorkingCap
A1: Working capital, capex and amortisation
A2: Line | B2: Unit | C2: Y1 | D2: Y2 | E2: Y3 | F2: Y4 | G2: Y5 | H2: Y6 | I2: Y7 | J2: Y8 | K2: Y9 | L2: Y10
A4: WORKING CAPITAL
A5: Sponsor receivables | B5: SaaS+take x AR days/365 | C5: =(Revenue!C24+Revenue!C25)*Assumptions!C89/365 -> 264.62219 | D5: =(Revenue!D24+Revenue!D25)*Assumptions!D89/365 -> 2111.1958 | E5: =(Revenue!E24+Revenue!E25)*Assumptions!E89/365 -> 12639.071 | F5: =(Revenue!F24+Revenue!F25)*Assumptions!F89/365 -> 37945.693 | G5: =(Revenue!G24+Revenue!G25)*Assumptions!G89/365 -> 78601.18 | H5: =(Revenue!H24+Revenue!H25)*Assumptions!H89/365 -> 134358.01 | I5: =(Revenue!I24+Revenue!I25)*Assumptions!I89/365 -> 194450.08 | J5: =(Revenue!J24+Revenue!J25)*Assumptions!J89/365 -> 251186.91 | ... L5: =(Revenue!L24+Revenue!L25)*Assumptions!L89/365 -> 348474.05
A6: Athlete payout float | B6: processed GMV owed, not yet paid | C6: =(Revenue!C10+Revenue!C15)*Assumptions!C88/365 -> 688.81849 | D6: =(Revenue!D10+Revenue!D15)*Assumptions!D88/365 -> 21062.538 | E6: =(Revenue!E10+Revenue!E15)*Assumptions!E88/365 -> 82246.27 | F6: =(Revenue!F10+Revenue!F15)*Assumptions!F88/365 -> 200719.68 | G6: =(Revenue!G10+Revenue!G15)*Assumptions!G88/365 -> 389531.04 | H6: =(Revenue!H10+Revenue!H15)*Assumptions!H88/365 -> 650150.8 | I6: =(Revenue!I10+Revenue!I15)*Assumptions!I88/365 -> 943175.45 | J6: =(Revenue!J10+Revenue!J15)*Assumptions!J88/365 -> 1224980.9 | ... L6: =(Revenue!L10+Revenue!L15)*Assumptions!L88/365 -> 1696540.3
A7: Trade payables | B7: opex x AP days/365 | C7: =Costs!C35*Assumptions!C90/365 -> 8991.1638 | D7: =Costs!D35*Assumptions!D90/365 -> 14645.36 | E7: =Costs!E35*Assumptions!E90/365 -> 20721.045 | F7: =Costs!F35*Assumptions!F90/365 -> 35208.864 | G7: =Costs!G35*Assumptions!G90/365 -> 59714.173 | H7: =Costs!H35*Assumptions!H90/365 -> 88106.593 | I7: =Costs!I35*Assumptions!I90/365 -> 110641.6 | J7: =Costs!J35*Assumptions!J90/365 -> 131089.5 | ... L7: =Costs!L35*Assumptions!L90/365 -> 162639.04
A8: Net working capital | B8: AR - float - AP | C8: =C5-C6-C7 -> -9415.3601 | D8: =D5-D6-D7 -> -33596.703 | E8: =E5-E6-E7 -> -90328.243 | F8: =F5-F6-F7 -> -197982.86 | G8: =G5-G6-G7 -> -370644.04 | H8: =H5-H6-H7 -> -603899.39 | I8: =I5-I6-I7 -> -859366.96 | J8: =J5-J6-J7 -> -1104883.5 | ... L8: =L5-L6-L7 -> -1510705.3
A9: Change in NWC | B9: cash impact | C9: =IF(1=1,C8,C8-C8) -> -9415.3601 | D9: =IF(2=1,D8,D8-C8) -> -24181.343 | E9: =IF(3=1,E8,E8-D8) -> -56731.54 | F9: =IF(4=1,F8,F8-E8) -> -107654.61 | G9: =IF(5=1,G8,G8-F8) -> -172661.18 | H9: =IF(6=1,H8,H8-G8) -> -233255.35 | I9: =IF(7=1,I8,I8-H8) -> -255467.58 | J9: =IF(8=1,J8,J8-I8) -> -245516.53 | K9: =IF(9=1,K8,K8-J8) -> -188361.55 | L9: =IF(10=1,L8,L8-K8) -> -217460.22
A11: CAPEX & AMORTISATION
A12: Capitalised development | B12: % of people cost | C12: =Costs!C17*Assumptions!C91 -> 11400 | D12: =Costs!D17*Assumptions!D91 -> 23400 | E12: =Costs!E17*Assumptions!E91 -> 27000 | F12: =Costs!F17*Assumptions!F91 -> 38400 | G12: =Costs!G17*Assumptions!G91 -> 79200 | H12: =Costs!H17*Assumptions!H91 -> 142800 | I12: =Costs!I17*Assumptions!I91 -> 210000 | J12: =Costs!J17*Assumptions!J91 -> 270000 | ... L12: =Costs!L17*Assumptions!L91 -> 364800
A13: Amortisation | B13: 3-yr straight line on trailing capex | C13: =SUM(OFFSET(C12,0,-MIN(Assumptions!C92-1,1-1),1,MIN(Assumptions!C92,1)))/Assumptions!C92 -> 3800 | D13: =SUM(OFFSET(D12,0,-MIN(Assumptions!D92-1,2-1),1,MIN(Assumptions!D92,2)))/Assumptions!D92 -> 11600 | E13: =SUM(OFFSET(E12,0,-MIN(Assumptions!E92-1,3-1),1,MIN(Assumptions!E92,3)))/Assumptions!E92 -> 20600 | F13: =SUM(OFFSET(F12,0,-MIN(Assumptions!F92-1,4-1),1,MIN(Assumptions!F92,4)))/Assumptions!F92 -> 29600 | G13: =SUM(OFFSET(G12,0,-MIN(Assumptions!G92-1,5-1),1,MIN(Assumptions!G92,5)))/Assumptions!G92 -> 48200 | H13: =SUM(OFFSET(H12,0,-MIN(Assumptions!H92-1,6-1),1,MIN(Assumptions!H92,6)))/Assumptions!H92 -> 86800 | I13: =SUM(OFFSET(I12,0,-MIN(Assumptions!I92-1,7-1),1,MIN(Assumptions!I92,7)))/Assumptions!I92 -> 144000 | J13: =SUM(OFFSET(J12,0,-MIN(Assumptions!J92-1,8-1),1,MIN(Assumptions!J92,8)))/Assumptions!J92 -> 207600 | K13: =SUM(OFFSET(K12,0,-MIN(Assumptions!K92-1,9-1),1,MIN(Assumptions!K92,9)))/Assumptions!K92 -> 267300 | L13: =SUM(OFFSET(L12,0,-MIN(Assumptions!L92-1,10-1),1,MIN(Assumptions!L92,10)))/Assumptions!L92 -> 318900
A14: Net intangible assets | B14: closing | C14: =C12-C13 -> 7600 | D14: =C14+D12-D13 -> 19400 | E14: =D14+E12-E13 -> 25800 | F14: =E14+F12-F13 -> 34600 | G14: =F14+G12-G13 -> 65600 | H14: =G14+H12-H13 -> 121600 | I14: =H14+I12-I13 -> 187600 | J14: =I14+J12-J13 -> 250000 | K14: =J14+K12-K13 -> 304600 | L14: =K14+L12-L13 -> 350500

Sheet P&L
A1: Income statement
A2: Line | B2: Unit | C2: Y1 | D2: Y2 | E2: Y3 | F2: Y4 | G2: Y5 | H2: Y6 | I2: Y7 | J2: Y8 | K2: Y9 | L2: Y10
A4: Net revenue | C4: =Revenue!C26 -> 2146.38 | D4: =Revenue!D26 -> 68373.784 | E4: =Revenue!E26 -> 286818.8 | F4: =Revenue!F26 -> 703667.36 | G4: =Revenue!G26 -> 1321350.1 | H4: =Revenue!H26 -> 2124048.5 | I4: =Revenue!I26 -> 3013163.2 | J4: =Revenue!J26 -> 3853438.1 | ... L4: =Revenue!L26 -> 5253768.6
A5: Cost of sales | C5: =-Costs!C14 -> -3422.7091 | D5: =-Costs!D14 -> -31857.287 | E5: =-Costs!E14 -> -106695.02 | F5: =-Costs!F14 -> -235197.48 | G5: =-Costs!G14 -> -421378.21 | H5: =-Costs!H14 -> -658989.57 | I5: =-Costs!I14 -> -923988.59 | J5: =-Costs!J14 -> -1175852.3 | ... L5: =-Costs!L14 -> -1591699.1
A6: GROSS PROFIT | C6: =C4+C5 -> -1276.3291 | D6: =D4+D5 -> 36516.497 | E6: =E4+E5 -> 180123.78 | F6: =F4+F5 -> 468469.87 | G6: =G4+G5 -> 899971.9 | H6: =H4+H5 -> 1465058.9 | I6: =I4+I5 -> 2089174.6 | J6: =J4+J5 -> 2677585.9 | ... L6: =L4+L5 -> 3662069.5
A7: Gross margin | C7: =C6/C4 -> -0.59464263 | D7: =D6/D4 -> 0.53407161 | E7: =E6/E4 -> 0.62800548 | F7: =F6/F4 -> 0.66575473 | G7: =G6/G4 -> 0.68110026 | H7: =H6/H4 -> 0.68974834 | I7: =I6/I4 -> 0.69334931 | J7: =J6/J4 -> 0.69485633 | ... L7: =L6/L4 -> 0.6970367
A9: Operating costs | C9: =-Costs!C35 -> -109392.49 | D9: =-Costs!D35 -> -178185.22 | E9: =-Costs!E35 -> -252106.04 | F9: =-Costs!F35 -> -428374.52 | G9: =-Costs!G35 -> -726522.44 | H9: =-Costs!H35 -> -1071963.5 | I9: =-Costs!I35 -> -1346139.4 | J9: =-Costs!J35 -> -1594922.2 | ... L9: =-Costs!L35 -> -1978775
A10: EBITDA | C10: =C6+C9 -> -110668.82 | D10: =D6+D9 -> -141668.72 | E10: =E6+E9 -> -71982.266 | F10: =F6+F9 -> 40095.355 | G10: =G6+G9 -> 173449.46 | H10: =H6+H9 -> 393095.35 | I10: =I6+I9 -> 743035.18 | J10: =J6+J9 -> 1082663.7 | ... L10: =L6+L9 -> 1683294.6
A11: EBITDA margin | C11: =C10/C4 -> -51.560685 | D11: =D10/D4 -> -2.0719743 | E11: =E10/E4 -> -0.25096774 | F11: =F10/F4 -> 0.056980552 | G11: =G10/G4 -> 0.13126684 | H11: =H10/H4 -> 0.18506892 | I11: =I10/I4 -> 0.24659639 | J11: =J10/J4 -> 0.28096043 | ... L11: =L10/L4 -> 0.32039754
A12: Amortisation | C12: =-WorkingCap!C13 -> -3800 | D12: =-WorkingCap!D13 -> -11600 | E12: =-WorkingCap!E13 -> -20600 | F12: =-WorkingCap!F13 -> -29600 | G12: =-WorkingCap!G13 -> -48200 | H12: =-WorkingCap!H13 -> -86800 | I12: =-WorkingCap!I13 -> -144000 | J12: =-WorkingCap!J13 -> -207600 | ... L12: =-WorkingCap!L13 -> -318900
A13: EBIT | C13: =C10+C12 -> -114468.82 | D13: =D10+D12 -> -153268.72 | E13: =E10+E12 -> -92582.266 | F13: =F10+F12 -> 10495.355 | G13: =G10+G12 -> 125249.46 | H13: =H10+H12 -> 306295.35 | I13: =I10+I12 -> 599035.18 | J13: =J10+J12 -> 875063.65 | ... L13: =L10+L12 -> 1364394.6
A15: TAX: with loss carryforward and the startup-rate step
A16: Losses brought forward | B16: accumulated | C16: =IF(1=1,0,MIN(0,C18)) -> 0 | D16: =IF(2=1,0,MIN(0,C18)) -> -114468.82 | E16: =IF(3=1,0,MIN(0,D18)) -> -267737.54 | F16: =IF(4=1,0,MIN(0,E18)) -> -360319.81 | G16: =IF(5=1,0,MIN(0,F18)) -> -349824.46 | H16: =IF(6=1,0,MIN(0,G18)) -> -224575 | I16: =IF(7=1,0,MIN(0,H18)) -> 0 | J16: =IF(8=1,0,MIN(0,I18)) -> 0 | K16: =IF(9=1,0,MIN(0,J18)) -> 0 | L16: =IF(10=1,0,MIN(0,K18)) -> 0
A17: Taxable profit | B17: after offset | C17: =MAX(0,C13+C16) -> 0 | D17: =MAX(0,D13+D16) -> 0 | E17: =MAX(0,E13+E16) -> 0 | F17: =MAX(0,F13+F16) -> 0 | G17: =MAX(0,G13+G16) -> 0 | H17: =MAX(0,H13+H16) -> 81720.357 | I17: =MAX(0,I13+I16) -> 599035.18 | J17: =MAX(0,J13+J16) -> 875063.65 | ... L17: =MAX(0,L13+L16) -> 1364394.6
A18: Losses carried forward | B18: running | C18: =MIN(0,C13) -> -114468.82 | D18: =MIN(0,D13+C18) -> -267737.54 | E18: =MIN(0,E13+D18) -> -360319.81 | F18: =MIN(0,F13+E18) -> -349824.46 | G18: =MIN(0,G13+F18) -> -224575 | H18: =MIN(0,H13+G18) -> 0 | I18: =MIN(0,I13+H18) -> 0 | J18: =MIN(0,J13+I18) -> 0 | K18: =MIN(0,K13+J18) -> 0 | L18: =MIN(0,L13+K18) -> 0
