Workbook

Sheet README
A1: Stride: Financial Model
A3: 10-year operating model, three statements, and a valuation. EUR. Y1 = 2027.
A5: COLOUR CODE
A6: LIGHT BLUE | B6: Estimated input
A7: LIGHT YELLOW | B7: Sourced input (Stripe pricing, Spanish tax law, AWS list)
A8: WHITE | B8: Computed formula
A9: LIGHT GREEN | B9: Dependent value, pulled from another sheet
A10: LIGHT GREY | B10: Total or subtotal
A11: LIGHT RED | B11: A check that must read zero
A13: SHEETS
A14: INPUTS
A15: Assumptions | B15: Every input and assumption taken into consideration
A17: BUILD-UP
A18: Drivers | B18: Athletes and fans, including monthly cohort churn
A19: Revenue | B19: GMV and net revenue, stream by stream
A20: Costs | B20: COGS and operating costs, line by line
A21: WorkingCap | B21: Receivables, payables, athlete float, capex, D&A
A23: THE THREE FINANCIAL STATEMENTS
A24: P&L | B24: Income statement
A25: CashFlow | B25: Cash flow statement, indirect method, tying to closing cash
A26: BalanceSheet | B26: Balance sheet, with an explicit check row so it must balance
A28: VALUATION AND FUNDING
A29: Valuation | B29: DCF, NPV, IRR, exit multiples, sensitivity
A30: Funding | B30: Funding rounds, dilution, ownership shares
A32: OPERATING PLANS
A33: HiringPlan | B33: Headcount by role, at Spanish loaded salaries
A34: CAC_CLV | B34: Acquisition cost against lifetime value
A35: KPIs | B35: Scale, quality of revenue, efficiency
A37: CONTROL
A38: Check | B38: Internal quality checks. Every variance row must read zero
A40: APPENDIX: RESEARCH AND MODELLING
A41: Comparables | B41: Published facts about Patreon, Passes and agents. The benchmarking source
A42: MarketModel | B42: Modelled assumptions, per market dynamics
A43: Research | B43: Where each baseline assumption came from, and how confident it is

Sheet Assumptions
A1: Assumptions, every input lives here
C2: Input: change me | E2: Sourced fact | G2: Formula (this sheet) | I2: Formula (other sheet) | K2: Total
A3: Line | B3: Unit | C3: Y1 | D3: Y2 | E3: Y3 | F3: Y4 | G3: Y5 | H3: Y6 | I3: Y7 | J3: Y8 | K3: Y9 | L3: Y10
A4: MARKET: the plan's shape
A5: Active athletes (year end) | B5: count | C5: 400 | D5: 1200 | E5: 3000 | F5: 6000 | G5: 10500 | H5: 16000 | I5: 22000 | J5: 28000 | K5: 34000 | L5: 40000
A6: Niche share of athletes | B6: % | C6: 0.95 | D6: 0.92 | E6: 0.8 | F6: 0.68 | G6: 0.58 | H6: 0.5 | I6: 0.45 | J6: 0.43 | K6: 0.42 | L6: 0.41
A7: Athletes needed for full SaaS value | B7: count | C7: 2000 | D7: =C7 | E7: =C7 | F7: =C7 | G7: =C7 | H7: =C7 | I7: =C7 | J7: =C7 | K7: =C7 | L7: =C7 | N7: Below this, sponsor conversion scales with supply, a matching product is worth nothing against an empty directory
A9: SEGMENT: NICHE
A10: Monetising athletes (niche) | B10: % of segment | C10: 0.28 | D10: 0.32 | E10: 0.37 | F10: 0.41 | G10: 0.44 | H10: 0.46 | I10: 0.48 | J10: 0.49 | K10: 0.5 | L10: 0.5
A11: Paying fans per monetising athlete (niche) | B11: count | C11: 20 | D11: 22 | E11: 25 | F11: 28 | G11: 30 | H11: 32 | I11: 34 | J11: 35 | K11: 36 | L11: 37 | N11: derived on MarketModel from Patreon members-per-creator
A12: Fan ARPU per month (niche) | B12: EUR | C12: 8 | D12: 8.3 | E12: 8.6 | F12: 8.8 | G12: 9 | H12: 9.1 | I12: 9.2 | J12: 9.3 | K12: 9.4 | L12: 9.5 | N12: derived on MarketModel from our tier mix, cross-checked against Patreon
A13: Fan churn per month (niche) | B13: % | C13: 0.09 | D13: 0.085 | E13: 0.08 | F13: 0.075 | G13: 0.07 | H13: 0.065 | I13: 0.06 | J13: 0.058 | K13: 0.056 | L13: 0.055 | N13: derived on MarketModel from Patreon churn and our annual-plan mix
A14: Athlete churn per year (niche) | B14: % | C14: 0.3 | D14: 0.27 | E14: 0.24 | F14: 0.22 | G14: 0.2 | H14: 0.19 | I14: 0.18 | J14: 0.17 | K14: 0.16 | L14: 0.16
A15: Max new fans per athlete per year (niche) | B15: capacity ceiling | C15: 30 | D15: 33 | E15: 36 | F15: 40 | G15: 43 | H15: 45 | I15: 47 | J15: 49 | K15: 50 | L15: 52 | N15: An audience is finite; without this ceiling higher churn RAISES revenue
A16: Athletes landing a deal (niche) | B16: % of segment | C16: 0.05 | D16: 0.07 | E16: 0.09 | F16: 0.11 | G16: 0.13 | H16: 0.15 | I16: 0.16 | J16: 0.17 | K16: 0.17 | L16: 0.18
A17: Deals per dealing athlete (niche) | B17: count | C17: 1.1 | D17: 1.2 | E17: 1.3 | F17: 1.5 | G17: 1.6 | H17: 1.7 | I17: 1.8 | J17: 1.9 | K17: 1.9 | L17: 2
A18: Average deal value (niche) | B18: EUR | C18: 900 | D18: 1050 | E18: 1200 | F18: 1350 | G18: 1500 | H18: 1600 | I18: 1700 | J18: 1800 | K18: 1900 | L18: 2000
A19: Athlete CAC (niche) | B19: EUR | C19: 16 | D19: 18 | E19: 21 | F19: 24 | G19: 27 | H19: 30 | I19: 32 | J19: 34 | K19: 35 | L19: 36
A21: SEGMENT: POPULAR
A22: Monetising athletes (popular) | B22: % of segment | C22: 0.14 | D22: 0.17 | E22: 0.2 | F22: 0.23 | G22: 0.26 | H22: 0.28 | I22: 0.3 | J22: 0.31 | K22: 0.32 | L22: 0.32
A23: Paying fans per monetising athlete (popular) | B23: count | C23: 26 | D23: 29 | E23: 32 | F23: 35 | G23: 38 | H23: 41 | I23: 44 | J23: 46 | K23: 47 | L23: 48 | N23: derived on MarketModel from Patreon members-per-creator
A24: Fan ARPU per month (popular) | B24: EUR | C24: 7 | D24: 7.2 | E24: 7.4 | F24: 7.6 | G24: 7.8 | H24: 7.9 | I24: 8 | J24: 8.1 | K24: 8.2 | L24: 8.3 | N24: derived on MarketModel from our tier mix, cross-checked against Patreon
A25: Fan churn per month (popular) | B25: % | C25: 0.13 | D25: 0.125 | E25: 0.12 | F25: 0.11 | G25: 0.105 | H25: 0.1 | I25: 0.09 | J25: 0.088 | K25: 0.086 | L25: 0.085 | N25: derived on MarketModel from Patreon churn and our annual-plan mix
A26: Athlete churn per year (popular) | B26: % | C26: 0.35 | D26: 0.32 | E26: 0.3 | F26: 0.27 | G26: 0.25 | H26: 0.23 | I26: 0.22 | J26: 0.21 | K26: 0.21 | L26: 0.2
A27: Max new fans per athlete per year (popular) | B27: capacity ceiling | C27: 38 | D27: 42 | E27: 46 | F27: 50 | G27: 54 | H27: 58 | I27: 62 | J27: 65 | K27: 67 | L27: 69 | N27: An audience is finite; without this ceiling higher churn RAISES revenue
A28: Athletes landing a deal (popular) | B28: % of segment | C28: 0.14 | D28: 0.17 | E28: 0.2 | F28: 0.24 | G28: 0.27 | H28: 0.29 | I28: 0.3 | J28: 0.31 | K28: 0.31 | L28: 0.32
A29: Deals per dealing athlete (popular) | B29: count | C29: 1.3 | D29: 1.5 | E29: 1.7 | F29: 1.9 | G29: 2.1 | H29: 2.3 | I29: 2.4 | J29: 2.5 | K29: 2.5 | L29: 2.6
A30: Average deal value (popular) | B30: EUR | C30: 2200 | D30: 2500 | E30: 2800 | F30: 3100 | G30: 3400 | H30: 3700 | I30: 4000 | J30: 4200 | K30: 4400 | L30: 4600
A31: Athlete CAC (popular) | B31: EUR | C31: 40 | D31: 46 | E31: 53 | F31: 60 | G31: 67 | H31: 73 | I31: 78 | J31: 82 | K31: 85 | L31: 88
A33: SPONSORS
A34: Registered sponsors | B34: count | C34: 25 | D34: 90 | E34: 230 | F34: 500 | G34: 900 | H34: 1400 | I34: 2000 | J34: 2600 | K34: 3100 | L34: 3600
A35: Share on a paid plan | B35: % | C35: 0.1 | D35: 0.14 | E35: 0.17 | F35: 0.19 | G35: 0.2 | H35: 0.2 | I35: 0.2 | J35: 0.2 | K35: 0.2 | L35: 0.2
A36: Sponsor plan ARPU per month | B36: EUR | C36: 199 | D36: 229 | E36: 260 | F36: 290 | G36: 320 | H36: 360 | I36: 400 | J36: 430 | K36: 455 | L36: 475
A37: Sponsor CAC | B37: EUR | C37: 900 | D37: 1050 | E37: 1200 | F37: 1400 | G37: 1600 | H37: 1750 | I37: 1900 | J37: 2000 | K37: 2100 | L37: 2200
A39: TAKE RATES & PAYMENT RAILS
A40: Take rate: fan revenue | B40: % | C40: 0.15 | D40: =C40 | E40: =C40 | F40: =C40 | G40: =C40 | H40: =C40 | I40: =C40 | J40: =C40 | K40: =C40 | L40: =C40 | N40: Our pricing decision. OnlyFans/Fansly/Fanfix 20%, Passes 10% + $29/mo
A41: Take rate: sponsorship, base | B41: % | C41: 0.1 | D41: =C41 | E41: =C41 | F41: =C41 | G41: =C41 | H41: =C41 | I41: =C41 | J41: =C41 | K41: =C41 | L41: =C41 | N41: Free and Starter plans. Agents take 10-20% of an endorsement
A42: Take rate: sponsorship, Scout Pro | B42: % | C42: 0.07 | D42: =C42 | E42: =C42 | F42: =C42 | G42: =C42 | H42: =C42 | I42: =C42 | J42: =C42 | K42: =C42 | L42: =C42 | N42: A sponsor paying for the tooling pays less on the deal
A43: Take rate: sponsorship, Scout Agency | B43: % | C43: 0.05 | D43: =C43 | E43: =C43 | F43: =C43 | G43: =C43 | H43: =C43 | I43: =C43 | J43: =C43 | K43: =C43 | L43: =C43 | N43: The most committed tier. Half what an agent charges at the low end
A44: Subscriber deal volume, multiple of average | B44: x | C44: 2 | D44: =C44 | E44: =C44 | F44: =C44 | G44: =C44 | H44: =C44 | I44: =C44 | J44: =C44 | K44: =C44 | L44: =C44 | N44: Subscribers buy campaign capacity, so they run more volume than the average sponsor. The only estimate in the tiering
...

Sheet Drivers
A1: Drivers: athletes and fans, with cohort churn
C2: Input: change me | E2: Sourced fact | G2: Formula (this sheet) | I2: Formula (other sheet) | K2: Total
A3: Line | B3: Unit | C3: Y1 | D3: Y2 | E3: Y3 | F3: Y4 | G3: Y5 | H3: Y6 | I3: Y7 | J3: Y8 | K3: Y9 | L3: Y10
A4: ATHLETES
A5: Total athletes (year end) | C5: =Assumptions!C5 | D5: =Assumptions!D5 | E5: =Assumptions!E5 | F5: =Assumptions!F5 | G5: =Assumptions!G5 | H5: =Assumptions!H5 | I5: =Assumptions!I5 | J5: =Assumptions!J5 | ... L5: =Assumptions!L5
A6: Niche athletes | C6: =Drivers!C5*Assumptions!C6 | D6: =Drivers!D5*Assumptions!D6 | E6: =Drivers!E5*Assumptions!E6 | F6: =Drivers!F5*Assumptions!F6 | G6: =Drivers!G5*Assumptions!G6 | H6: =Drivers!H5*Assumptions!H6 | I6: =Drivers!I5*Assumptions!I6 | J6: =Drivers!J5*Assumptions!J6 | ... L6: =Drivers!L5*Assumptions!L6
A7: Popular athletes | C7: =Drivers!C5-Drivers!C6 | D7: =Drivers!D5-Drivers!D6 | E7: =Drivers!E5-Drivers!E6 | F7: =Drivers!F5-Drivers!F6 | G7: =Drivers!G5-Drivers!G6 | H7: =Drivers!H5-Drivers!H6 | I7: =Drivers!I5-Drivers!I6 | J7: =Drivers!J5-Drivers!J6 | ... L7: =Drivers!L5-Drivers!L6
A9: NICHE: fans and churn
A10: Niche athletes lost to churn | C10: =IF(1=1,0,C6*Assumptions!C14) | D10: =IF(2=1,0,C6*Assumptions!D14) | E10: =IF(3=1,0,D6*Assumptions!E14) | F10: =IF(4=1,0,E6*Assumptions!F14) | G10: =IF(5=1,0,F6*Assumptions!G14) | H10: =IF(6=1,0,G6*Assumptions!H14) | I10: =IF(7=1,0,H6*Assumptions!I14) | J10: =IF(8=1,0,I6*Assumptions!J14) | K10: =IF(9=1,0,J6*Assumptions!K14) | L10: =IF(10=1,0,K6*Assumptions!L14)
A11: Niche athletes acquired (gross) | C11: =MAX(0,C6-IF(1=1,0,C6)+C10) | D11: =MAX(0,D6-IF(2=1,0,C6)+D10) | E11: =MAX(0,E6-IF(3=1,0,D6)+E10) | F11: =MAX(0,F6-IF(4=1,0,E6)+F10) | G11: =MAX(0,G6-IF(5=1,0,F6)+G10) | H11: =MAX(0,H6-IF(6=1,0,G6)+H10) | I11: =MAX(0,I6-IF(7=1,0,H6)+I10) | J11: =MAX(0,J6-IF(8=1,0,I6)+J10) | K11: =MAX(0,K6-IF(9=1,0,J6)+K10) | L11: =MAX(0,L6-IF(10=1,0,K6)+L10)
A12: Niche monetising athletes | C12: =C6*Assumptions!C10 | D12: =D6*Assumptions!D10 | E12: =E6*Assumptions!E10 | F12: =F6*Assumptions!F10 | G12: =G6*Assumptions!G10 | H12: =H6*Assumptions!H10 | I12: =I6*Assumptions!I10 | J12: =J6*Assumptions!J10 | ... L12: =L6*Assumptions!L10
A13: Niche paying fans (target, year end) | C13: =C12*Assumptions!C11 | D13: =D12*Assumptions!D11 | E13: =E12*Assumptions!E11 | F13: =F12*Assumptions!F11 | G13: =G12*Assumptions!G11 | H13: =H12*Assumptions!H11 | I13: =I12*Assumptions!I11 | J13: =J12*Assumptions!J11 | ... L13: =L12*Assumptions!L11
A14: Niche monthly retention r = 1-churn | B14: factor | C14: =1-Assumptions!C13 | D14: =1-Assumptions!D13 | E14: =1-Assumptions!E13 | F14: =1-Assumptions!F13 | G14: =1-Assumptions!G13 | H14: =1-Assumptions!H13 | I14: =1-Assumptions!I13 | J14: =1-Assumptions!J13 | ... L14: =1-Assumptions!L13
A15: Niche opening fans survived 12 months | B15: open x r^12 | C15: =0 | D15: =C17*D14^12 | E15: =D17*E14^12 | F15: =E17*F14^12 | G15: =F17*G14^12 | H15: =G17*H14^12 | I15: =H17*I14^12 | J15: =I17*J14^12 | K15: =J17*K14^12 | L15: =K17*L14^12
A16: Niche monthly gross adds | B16: solved, then capped by capacity | C16: =MIN(MAX(0,(C13-C15)/((1-C14^12)/(1-C14))),C12*Assumptions!C15/12) | D16: =MIN(MAX(0,(D13-D15)/((1-D14^12)/(1-D14))),D12*Assumptions!D15/12) | E16: =MIN(MAX(0,(E13-E15)/((1-E14^12)/(1-E14))),E12*Assumptions!E15/12) | F16: =MIN(MAX(0,(F13-F15)/((1-F14^12)/(1-F14))),F12*Assumptions!F15/12) | G16: =MIN(MAX(0,(G13-G15)/((1-G14^12)/(1-G14))),G12*Assumptions!G15/12) | H16: =MIN(MAX(0,(H13-H15)/((1-H14^12)/(1-H14))),H12*Assumptions!H15/12) | I16: =MIN(MAX(0,(I13-I15)/((1-I14^12)/(1-I14))),I12*Assumptions!I15/12) | J16: =MIN(MAX(0,(J13-J15)/((1-J14^12)/(1-J14))),J12*Assumptions!J15/12) | ... L16: =MIN(MAX(0,(L13-L15)/((1-L14^12)/(1-L14))),L12*Assumptions!L15/12)
A17: Niche paying fans (year end) | B17: survivors + capped adds | C17: =C15+C16*(1-C14^12)/(1-C14) | D17: =D15+D16*(1-D14^12)/(1-D14) | E17: =E15+E16*(1-E14^12)/(1-E14) | F17: =F15+F16*(1-F14^12)/(1-F14) | G17: =G15+G16*(1-G14^12)/(1-G14) | H17: =H15+H16*(1-H14^12)/(1-H14) | I17: =I15+I16*(1-I14^12)/(1-I14) | J17: =J15+J16*(1-J14^12)/(1-J14) | ... L17: =L15+L16*(1-L14^12)/(1-L14)
A18: Niche fans acquired (gross) | B18: x12 months | C18: =C16*12 | D18: =D16*12 | E18: =E16*12 | F18: =F16*12 | G18: =G16*12 | H18: =H16*12 | I18: =I16*12 | J18: =J16*12 | ... L18: =L16*12
A19: Niche S = r(1-r^12)/(1-r) | B19: geometric sum | C19: =C14*(1-C14^12)/(1-C14) | D19: =D14*(1-D14^12)/(1-D14) | E19: =E14*(1-E14^12)/(1-E14) | F19: =F14*(1-F14^12)/(1-F14) | G19: =G14*(1-G14^12)/(1-G14) | H19: =H14*(1-H14^12)/(1-H14) | I19: =I14*(1-I14^12)/(1-I14) | J19: =J14*(1-J14^12)/(1-J14) | ... L19: =L14*(1-L14^12)/(1-L14)
A20: Niche average fans during year | B20: exact mean, revenue basis | C20: =(C16/(1-C14)*(12-C19))/12 | D20: =(C17*D19+D16/(1-D14)*(12-D19))/12 | E20: =(D17*E19+E16/(1-E14)*(12-E19))/12 | F20: =(E17*F19+F16/(1-F14)*(12-F19))/12 | G20: =(F17*G19+G16/(1-G14)*(12-G19))/12 | H20: =(G17*H19+H16/(1-H14)*(12-H19))/12 | I20: =(H17*I19+I16/(1-I14)*(12-I19))/12 | J20: =(I17*J19+J16/(1-J14)*(12-J19))/12 | K20: =(J17*K19+K16/(1-K14)*(12-K19))/12 | L20: =(K17*L19+L16/(1-L14)*(12-L19))/12
A21: Niche fans lost to churn | B21: avg x churn x 12 | C21: =C20*12*Assumptions!C13 | D21: =D20*12*Assumptions!D13 | E21: =E20*12*Assumptions!E13 | F21: =F20*12*Assumptions!F13 | G21: =G20*12*Assumptions!G13 | H21: =H20*12*Assumptions!H13 | I21: =I20*12*Assumptions!I13 | J21: =J20*12*Assumptions!J13 | ... L21: =L20*12*Assumptions!L13
A23: POPULAR: fans and churn
A24: Popular athletes lost to churn | C24: =IF(1=1,0,C7*Assumptions!C26) | D24: =IF(2=1,0,C7*Assumptions!D26) | E24: =IF(3=1,0,D7*Assumptions!E26) | F24: =IF(4=1,0,E7*Assumptions!F26) | G24: =IF(5=1,0,F7*Assumptions!G26) | H24: =IF(6=1,0,G7*Assumptions!H26) | I24: =IF(7=1,0,H7*Assumptions!I26) | J24: =IF(8=1,0,I7*Assumptions!J26) | K24: =IF(9=1,0,J7*Assumptions!K26) | L24: =IF(10=1,0,K7*Assumptions!L26)
A25: Popular athletes acquired (gross) | C25: =MAX(0,C7-IF(1=1,0,C7)+C24) | D25: =MAX(0,D7-IF(2=1,0,C7)+D24) | E25: =MAX(0,E7-IF(3=1,0,D7)+E24) | F25: =MAX(0,F7-IF(4=1,0,E7)+F24) | G25: =MAX(0,G7-IF(5=1,0,F7)+G24) | H25: =MAX(0,H7-IF(6=1,0,G7)+H24) | I25: =MAX(0,I7-IF(7=1,0,H7)+I24) | J25: =MAX(0,J7-IF(8=1,0,I7)+J24) | K25: =MAX(0,K7-IF(9=1,0,J7)+K24) | L25: =MAX(0,L7-IF(10=1,0,K7)+L24)
A26: Popular monetising athletes | C26: =C7*Assumptions!C22 | D26: =D7*Assumptions!D22 | E26: =E7*Assumptions!E22 | F26: =F7*Assumptions!F22 | G26: =G7*Assumptions!G22 | H26: =H7*Assumptions!H22 | I26: =I7*Assumptions!I22 | J26: =J7*Assumptions!J22 | ... L26: =L7*Assumptions!L22
A27: Popular paying fans (target, year end) | C27: =C26*Assumptions!C23 | D27: =D26*Assumptions!D23 | E27: =E26*Assumptions!E23 | F27: =F26*Assumptions!F23 | G27: =G26*Assumptions!G23 | H27: =H26*Assumptions!H23 | I27: =I26*Assumptions!I23 | J27: =J26*Assumptions!J23 | ... L27: =L26*Assumptions!L23
A28: Popular monthly retention r = 1-churn | B28: factor | C28: =1-Assumptions!C25 | D28: =1-Assumptions!D25 | E28: =1-Assumptions!E25 | F28: =1-Assumptions!F25 | G28: =1-Assumptions!G25 | H28: =1-Assumptions!H25 | I28: =1-Assumptions!I25 | J28: =1-Assumptions!J25 | ... L28: =1-Assumptions!L25
A29: Popular opening fans survived 12 months | B29: open x r^12 | C29: =0 | D29: =C31*D28^12 | E29: =D31*E28^12 | F29: =E31*F28^12 | G29: =F31*G28^12 | H29: =G31*H28^12 | I29: =H31*I28^12 | J29: =I31*J28^12 | K29: =J31*K28^12 | L29: =K31*L28^12
A30: Popular monthly gross adds | B30: solved, then capped by capacity | C30: =MIN(MAX(0,(C27-C29)/((1-C28^12)/(1-C28))),C26*Assumptions!C27/12) | D30: =MIN(MAX(0,(D27-D29)/((1-D28^12)/(1-D28))),D26*Assumptions!D27/12) | E30: =MIN(MAX(0,(E27-E29)/((1-E28^12)/(1-E28))),E26*Assumptions!E27/12) | F30: =MIN(MAX(0,(F27-F29)/((1-F28^12)/(1-F28))),F26*Assumptions!F27/12) | G30: =MIN(MAX(0,(G27-G29)/((1-G28^12)/(1-G28))),G26*Assumptions!G27/12) | H30: =MIN(MAX(0,(H27-H29)/((1-H28^12)/(1-H28))),H26*Assumptions!H27/12) | I30: =MIN(MAX(0,(I27-I29)/((1-I28^12)/(1-I28))),I26*Assumptions!I27/12) | J30: =MIN(MAX(0,(J27-J29)/((1-J28^12)/(1-J28))),J26*Assumptions!J27/12) | ... L30: =MIN(MAX(0,(L27-L29)/((1-L28^12)/(1-L28))),L26*Assumptions!L27/12)
A31: Popular paying fans (year end) | B31: survivors + capped adds | C31: =C29+C30*(1-C28^12)/(1-C28) | D31: =D29+D30*(1-D28^12)/(1-D28) | E31: =E29+E30*(1-E28^12)/(1-E28) | F31: =F29+F30*(1-F28^12)/(1-F28) | G31: =G29+G30*(1-G28^12)/(1-G28) | H31: =H29+H30*(1-H28^12)/(1-H28) | I31: =I29+I30*(1-I28^12)/(1-I28) | J31: =J29+J30*(1-J28^12)/(1-J28) | ... L31: =L29+L30*(1-L28^12)/(1-L28)
A32: Popular fans acquired (gross) | B32: x12 months | C32: =C30*12 | D32: =D30*12 | E32: =E30*12 | F32: =F30*12 | G32: =G30*12 | H32: =H30*12 | I32: =I30*12 | J32: =J30*12 | ... L32: =L30*12
A33: Popular S = r(1-r^12)/(1-r) | B33: geometric sum | C33: =C28*(1-C28^12)/(1-C28) | D33: =D28*(1-D28^12)/(1-D28) | E33: =E28*(1-E28^12)/(1-E28) | F33: =F28*(1-F28^12)/(1-F28) | G33: =G28*(1-G28^12)/(1-G28) | H33: =H28*(1-H28^12)/(1-H28) | I33: =I28*(1-I28^12)/(1-I28) | J33: =J28*(1-J28^12)/(1-J28) | ... L33: =L28*(1-L28^12)/(1-L28)
A34: Popular average fans during year | B34: exact mean, revenue basis | C34: =(C30/(1-C28)*(12-C33))/12 | D34: =(C31*D33+D30/(1-D28)*(12-D33))/12 | E34: =(D31*E33+E30/(1-E28)*(12-E33))/12 | F34: =(E31*F33+F30/(1-F28)*(12-F33))/12 | G34: =(F31*G33+G30/(1-G28)*(12-G33))/12 | H34: =(G31*H33+H30/(1-H28)*(12-H33))/12 | I34: =(H31*I33+I30/(1-I28)*(12-I33))/12 | J34: =(I31*J33+J30/(1-J28)*(12-J33))/12 | K34: =(J31*K33+K30/(1-K28)*(12-K33))/12 | L34: =(K31*L33+L30/(1-L28)*(12-L33))/12
A35: Popular fans lost to churn | B35: avg x churn x 12 | C35: =C34*12*Assumptions!C25 | D35: =D34*12*Assumptions!D25 | E35: =E34*12*Assumptions!E25 | F35: =F34*12*Assumptions!F25 | G35: =G34*12*Assumptions!G25 | H35: =H34*12*Assumptions!H25 | I35: =I34*12*Assumptions!I25 | J35: =J34*12*Assumptions!J25 | ... L35: =L34*12*Assumptions!L25
A37: TOTALS
A38: Paying fans (year end) | C38: =C17+C31 | D38: =D17+D31 | E38: =E17+E31 | F38: =F17+F31 | G38: =G17+G31 | H38: =H17+H31 | I38: =I17+I31 | J38: =J17+J31 | ... L38: =L17+L31
A39: Average paying fans | C39: =C20+C34 | D39: =D20+D34 | E39: =E20+E34 | F39: =F20+F34 | G39: =G20+G34 | H39: =H20+H34 | I39: =I20+I34 | J39: =J20+J34 | ... L39: =L20+L34
A40: Athletes acquired (gross) | C40: =C11+C25 | D40: =D11+D25 | E40: =E11+E25 | F40: =F11+F25 | G40: =G11+G25 | H40: =H11+H25 | I40: =I11+I25 | J40: =J11+J25 | ... L40: =L11+L25
A41: Fans lost to churn | C41: =C21+C35 | D41: =D21+D35 | E41: =E21+E35 | F41: =F21+F35 | G41: =G21+G35 | H41: =H21+H35 | I41: =I21+I35 | J41: =J21+J35 | ... L41: =L21+L35
A43: DEALS
A44: Niche deals | C44: =C6*Assumptions!C16*Assumptions!C17 | D44: =D6*Assumptions!D16*Assumptions!D17 | E44: =E6*Assumptions!E16*Assumptions!E17 | F44: =F6*Assumptions!F16*Assumptions!F17 | G44: =G6*Assumptions!G16*Assumptions!G17 | H44: =H6*Assumptions!H16*Assumptions!H17 | I44: =I6*Assumptions!I16*Assumptions!I17 | J44: =J6*Assumptions!J16*Assumptions!J17 | ... L44: =L6*Assumptions!L16*Assumptions!L17
...

Sheet Revenue
A1: Revenue: GMV built stream by stream, then our take
C2: Input: change me | E2: Sourced fact | G2: Formula (this sheet) | I2: Formula (other sheet) | K2: Total
A3: Line | B3: Unit | C3: Y1 | D3: Y2 | E3: Y3 | F3: Y4 | G3: Y5 | H3: Y6 | I3: Y7 | J3: Y8 | K3: Y9 | L3: Y10
A4: FAN GMV: what fans pay athletes, net of VAT
A5: Niche subscription GMV | B5: avg fans x ARPU x 12, ex-VAT | C5: =Drivers!C20*Assumptions!C12*12/(1+Assumptions!C48) | D5: =Drivers!D20*Assumptions!D12*12/(1+Assumptions!D48) | E5: =Drivers!E20*Assumptions!E12*12/(1+Assumptions!E48) | F5: =Drivers!F20*Assumptions!F12*12/(1+Assumptions!F48) | G5: =Drivers!G20*Assumptions!G12*12/(1+Assumptions!G48) | H5: =Drivers!H20*Assumptions!H12*12/(1+Assumptions!H48) | I5: =Drivers!I20*Assumptions!I12*12/(1+Assumptions!I48) | J5: =Drivers!J20*Assumptions!J12*12/(1+Assumptions!J48) | ... L5: =Drivers!L20*Assumptions!L12*12/(1+Assumptions!L48)
A6: Popular subscription GMV | B6: ex-VAT | C6: =Drivers!C34*Assumptions!C24*12/(1+Assumptions!C48) | D6: =Drivers!D34*Assumptions!D24*12/(1+Assumptions!D48) | E6: =Drivers!E34*Assumptions!E24*12/(1+Assumptions!E48) | F6: =Drivers!F34*Assumptions!F24*12/(1+Assumptions!F48) | G6: =Drivers!G34*Assumptions!G24*12/(1+Assumptions!G48) | H6: =Drivers!H34*Assumptions!H24*12/(1+Assumptions!H48) | I6: =Drivers!I34*Assumptions!I24*12/(1+Assumptions!I48) | J6: =Drivers!J34*Assumptions!J24*12/(1+Assumptions!J48) | ... L6: =Drivers!L34*Assumptions!L24*12/(1+Assumptions!L48)
A7: Subscription GMV | C7: =C5+C6 | D7: =D5+D6 | E7: =E5+E6 | F7: =F5+F6 | G7: =G5+G6 | H7: =H5+H6 | I7: =I5+I6 | J7: =J5+J6 | ... L7: =L5+L6
A8: PPV and tips GMV | B8: x multiple | C8: =C7*Assumptions!C49 | D8: =D7*Assumptions!D49 | E8: =E7*Assumptions!E49 | F8: =F7*Assumptions!F49 | G8: =G7*Assumptions!G49 | H8: =H7*Assumptions!H49 | I8: =I7*Assumptions!I49 | J8: =J7*Assumptions!J49 | ... L8: =L7*Assumptions!L49
A9: Total fan GMV | B9: ex-VAT, the take base | C9: =C7+C8 | D9: =D7+D8 | E9: =E7+E8 | F9: =F7+F8 | G9: =G7+G8 | H9: =H7+H8 | I9: =I7+I8 | J9: =J7+J8 | ... L9: =L7+L8
A10: Fan GMV including VAT | B10: what cards are charged | C10: =C9*(1+Assumptions!C48) | D10: =D9*(1+Assumptions!D48) | E10: =E9*(1+Assumptions!E48) | F10: =F9*(1+Assumptions!F48) | G10: =G9*(1+Assumptions!G48) | H10: =H9*(1+Assumptions!H48) | I10: =I9*(1+Assumptions!I48) | J10: =J9*(1+Assumptions!J48) | ... L10: =L9*(1+Assumptions!L48)
A12: SPONSORSHIP GMV: what sponsors pay athletes and clubs
A13: Niche sponsorship GMV | C13: =Drivers!C44*Assumptions!C18 | D13: =Drivers!D44*Assumptions!D18 | E13: =Drivers!E44*Assumptions!E18 | F13: =Drivers!F44*Assumptions!F18 | G13: =Drivers!G44*Assumptions!G18 | H13: =Drivers!H44*Assumptions!H18 | I13: =Drivers!I44*Assumptions!I18 | J13: =Drivers!J44*Assumptions!J18 | ... L13: =Drivers!L44*Assumptions!L18
A14: Popular sponsorship GMV | C14: =Drivers!C45*Assumptions!C30 | D14: =Drivers!D45*Assumptions!D30 | E14: =Drivers!E45*Assumptions!E30 | F14: =Drivers!F45*Assumptions!F30 | G14: =Drivers!G45*Assumptions!G30 | H14: =Drivers!H45*Assumptions!H30 | I14: =Drivers!I45*Assumptions!I30 | J14: =Drivers!J45*Assumptions!J30 | ... L14: =Drivers!L45*Assumptions!L30
A15: Total sponsorship GMV | C15: =C13+C14 | D15: =D13+D14 | E15: =E13+E14 | F15: =F13+F14 | G15: =G13+G14 | H15: =H13+H14 | I15: =I13+I14 | J15: =J13+J14 | ... L15: =L13+L14
A16: Agency share of subscribers | C16: =MAX(0,(Assumptions!C36-Assumptions!C46)/(Assumptions!C47-Assumptions!C46)) | D16: =MAX(0,(Assumptions!D36-Assumptions!D46)/(Assumptions!D47-Assumptions!D46)) | E16: =MAX(0,(Assumptions!E36-Assumptions!E46)/(Assumptions!E47-Assumptions!E46)) | F16: =MAX(0,(Assumptions!F36-Assumptions!F46)/(Assumptions!F47-Assumptions!F46)) | G16: =MAX(0,(Assumptions!G36-Assumptions!G46)/(Assumptions!G47-Assumptions!G46)) | H16: =MAX(0,(Assumptions!H36-Assumptions!H46)/(Assumptions!H47-Assumptions!H46)) | I16: =MAX(0,(Assumptions!I36-Assumptions!I46)/(Assumptions!I47-Assumptions!I46)) | J16: =MAX(0,(Assumptions!J36-Assumptions!J46)/(Assumptions!J47-Assumptions!J46)) | ... L16: =MAX(0,(Assumptions!L36-Assumptions!L46)/(Assumptions!L47-Assumptions!L46))
A17: Starter share of subscribers | C17: =MAX(0,(Assumptions!C46-Assumptions!C36)/(Assumptions!C46-Assumptions!C45)) | D17: =MAX(0,(Assumptions!D46-Assumptions!D36)/(Assumptions!D46-Assumptions!D45)) | E17: =MAX(0,(Assumptions!E46-Assumptions!E36)/(Assumptions!E46-Assumptions!E45)) | F17: =MAX(0,(Assumptions!F46-Assumptions!F36)/(Assumptions!F46-Assumptions!F45)) | G17: =MAX(0,(Assumptions!G46-Assumptions!G36)/(Assumptions!G46-Assumptions!G45)) | H17: =MAX(0,(Assumptions!H46-Assumptions!H36)/(Assumptions!H46-Assumptions!H45)) | I17: =MAX(0,(Assumptions!I46-Assumptions!I36)/(Assumptions!I46-Assumptions!I45)) | J17: =MAX(0,(Assumptions!J46-Assumptions!J36)/(Assumptions!J46-Assumptions!J45)) | ... L17: =MAX(0,(Assumptions!L46-Assumptions!L36)/(Assumptions!L46-Assumptions!L45))
A18: Subscriber share of deal volume | C18: =MIN(1,Assumptions!C35*Assumptions!C44) | D18: =MIN(1,Assumptions!D35*Assumptions!D44) | E18: =MIN(1,Assumptions!E35*Assumptions!E44) | F18: =MIN(1,Assumptions!F35*Assumptions!F44) | G18: =MIN(1,Assumptions!G35*Assumptions!G44) | H18: =MIN(1,Assumptions!H35*Assumptions!H44) | I18: =MIN(1,Assumptions!I35*Assumptions!I44) | J18: =MIN(1,Assumptions!J35*Assumptions!J44) | ... L18: =MIN(1,Assumptions!L35*Assumptions!L44)
A19: Effective sponsorship take | C19: =(1-C18)*Assumptions!C41+C18*(C17*Assumptions!C41+(1-C17-C16)*Assumptions!C42+C16*Assumptions!C43) | D19: =(1-D18)*Assumptions!D41+D18*(D17*Assumptions!D41+(1-D17-D16)*Assumptions!D42+D16*Assumptions!D43) | E19: =(1-E18)*Assumptions!E41+E18*(E17*Assumptions!E41+(1-E17-E16)*Assumptions!E42+E16*Assumptions!E43) | F19: =(1-F18)*Assumptions!F41+F18*(F17*Assumptions!F41+(1-F17-F16)*Assumptions!F42+F16*Assumptions!F43) | G19: =(1-G18)*Assumptions!G41+G18*(G17*Assumptions!G41+(1-G17-G16)*Assumptions!G42+G16*Assumptions!G43) | H19: =(1-H18)*Assumptions!H41+H18*(H17*Assumptions!H41+(1-H17-H16)*Assumptions!H42+H16*Assumptions!H43) | I19: =(1-I18)*Assumptions!I41+I18*(I17*Assumptions!I41+(1-I17-I16)*Assumptions!I42+I16*Assumptions!I43) | J19: =(1-J18)*Assumptions!J41+J18*(J17*Assumptions!J41+(1-J17-J16)*Assumptions!J42+J16*Assumptions!J43) | ... L19: =(1-L18)*Assumptions!L41+L18*(L17*Assumptions!L41+(1-L17-L16)*Assumptions!L42+L16*Assumptions!L43)
A20: TOTAL GMV | C20: =C9+C15 | D20: =D9+D15 | E20: =E9+E15 | F20: =F9+F15 | G20: =G9+G15 | H20: =H9+H15 | I20: =I9+I15 | J20: =J9+J15 | ... L20: =L9+L15
A22: NET REVENUE: our share
A23: Fan take | B23: fan GMV x take rate | C23: =C9*Assumptions!C40 | D23: =D9*Assumptions!D40 | E23: =E9*Assumptions!E40 | F23: =F9*Assumptions!F40 | G23: =G9*Assumptions!G40 | H23: =H9*Assumptions!H40 | I23: =I9*Assumptions!I40 | J23: =J9*Assumptions!J40 | ... L23: =L9*Assumptions!L40
A24: Sponsorship take | C24: =C15*C19 | D24: =D15*D19 | E24: =E15*E19 | F24: =F15*F19 | G24: =G15*G19 | H24: =H15*H19 | I24: =I15*I19 | J24: =J15*J19 | ... L24: =L15*L19
A25: Sponsor SaaS | B25: paying sponsors x ARPU x 12 | C25: =Drivers!C48*Assumptions!C36*12 | D25: =Drivers!D48*Assumptions!D36*12 | E25: =Drivers!E48*Assumptions!E36*12 | F25: =Drivers!F48*Assumptions!F36*12 | G25: =Drivers!G48*Assumptions!G36*12 | H25: =Drivers!H48*Assumptions!H36*12 | I25: =Drivers!I48*Assumptions!I36*12 | J25: =Drivers!J48*Assumptions!J36*12 | ... L25: =Drivers!L48*Assumptions!L36*12
A26: NET REVENUE | C26: =SUM(C23:C25) | D26: =SUM(D23:D25) | E26: =SUM(E23:E25) | F26: =SUM(F23:F25) | G26: =SUM(G23:G25) | H26: =SUM(H23:H25) | I26: =SUM(I23:I25) | J26: =SUM(J23:J25) | ... L26: =SUM(L23:L25)
A27: Growth | B27: % YoY | C27: =IF(1=1,"",C26/C26-1) | D27: =IF(2=1,"",D26/C26-1) | E27: =IF(3=1,"",E26/D26-1) | F27: =IF(4=1,"",F26/E26-1) | G27: =IF(5=1,"",G26/F26-1) | H27: =IF(6=1,"",H26/G26-1) | I27: =IF(7=1,"",I26/H26-1) | J27: =IF(8=1,"",J26/I26-1) | K27: =IF(9=1,"",K26/J26-1) | L27: =IF(10=1,"",L26/K26-1)
A28: Take rate on GMV | B28: blended | C28: =C26/C20 | D28: =D26/D20 | E28: =E26/E20 | F28: =F26/F20 | G28: =G26/G20 | H28: =H26/H20 | I28: =I26/I20 | J28: =J26/J20 | ... L28: =L26/L20

Sheet Costs
A1: Costs: every line built from its driver
C2: Input: change me | E2: Sourced fact | G2: Formula (this sheet) | I2: Formula (other sheet) | K2: Total
A3: Line | B3: Unit | C3: Y1 | D3: Y2 | E3: Y3 | F3: Y4 | G3: Y5 | H3: Y6 | I3: Y7 | J3: Y8 | K3: Y9 | L3: Y10
A4: COST OF SALES
A5: Fan transactions | B5: fan GMV incl VAT / avg ticket | C5: =Revenue!C10/Assumptions!C54 | D5: =Revenue!D10/Assumptions!D54 | E5: =Revenue!E10/Assumptions!E54 | F5: =Revenue!F10/Assumptions!F54 | G5: =Revenue!G10/Assumptions!G54 | H5: =Revenue!H10/Assumptions!H54 | I5: =Revenue!I10/Assumptions!I54 | J5: =Revenue!J10/Assumptions!J54 | ... L5: =Revenue!L10/Assumptions!L54
A6: Deal transactions | B6: count | C6: =Revenue!C15/Assumptions!C55 | D6: =Revenue!D15/Assumptions!D55 | E6: =Revenue!E15/Assumptions!E55 | F6: =Revenue!F15/Assumptions!F55 | G6: =Revenue!G15/Assumptions!G55 | H6: =Revenue!H15/Assumptions!H55 | I6: =Revenue!I15/Assumptions!I55 | J6: =Revenue!J15/Assumptions!J55 | ... L6: =Revenue!L15/Assumptions!L55
A7: Payment processing | B7: % of processed + fixed | C7: =(Revenue!C10+Revenue!C15)*Assumptions!C50+(C5+C6)*Assumptions!C51 | D7: =(Revenue!D10+Revenue!D15)*Assumptions!D50+(D5+D6)*Assumptions!D51 | E7: =(Revenue!E10+Revenue!E15)*Assumptions!E50+(E5+E6)*Assumptions!E51 | F7: =(Revenue!F10+Revenue!F15)*Assumptions!F50+(F5+F6)*Assumptions!F51 | G7: =(Revenue!G10+Revenue!G15)*Assumptions!G50+(G5+G6)*Assumptions!G51 | H7: =(Revenue!H10+Revenue!H15)*Assumptions!H50+(H5+H6)*Assumptions!H51 | I7: =(Revenue!I10+Revenue!I15)*Assumptions!I50+(I5+I6)*Assumptions!I51 | J7: =(Revenue!J10+Revenue!J15)*Assumptions!J50+(J5+J6)*Assumptions!J51 | ... L7: =(Revenue!L10+Revenue!L15)*Assumptions!L50+(L5+L6)*Assumptions!L51
A8: Payouts to athletes | B8: % + fixed | C8: =(Revenue!C10+Revenue!C15)*Assumptions!C52+(C5/30+C6)*Assumptions!C53 | D8: =(Revenue!D10+Revenue!D15)*Assumptions!D52+(D5/30+D6)*Assumptions!D53 | E8: =(Revenue!E10+Revenue!E15)*Assumptions!E52+(E5/30+E6)*Assumptions!E53 | F8: =(Revenue!F10+Revenue!F15)*Assumptions!F52+(F5/30+F6)*Assumptions!F53 | G8: =(Revenue!G10+Revenue!G15)*Assumptions!G52+(G5/30+G6)*Assumptions!G53 | H8: =(Revenue!H10+Revenue!H15)*Assumptions!H52+(H5/30+H6)*Assumptions!H53 | I8: =(Revenue!I10+Revenue!I15)*Assumptions!I52+(I5/30+I6)*Assumptions!I53 | J8: =(Revenue!J10+Revenue!J15)*Assumptions!J52+(J5/30+J6)*Assumptions!J53 | ... L8: =(Revenue!L10+Revenue!L15)*Assumptions!L52+(L5/30+L6)*Assumptions!L53
A9: Media egress GB | B9: GB/yr | C9: =Drivers!C39*Assumptions!C59*12 | D9: =Drivers!D39*Assumptions!D59*12 | E9: =Drivers!E39*Assumptions!E59*12 | F9: =Drivers!F39*Assumptions!F59*12 | G9: =Drivers!G39*Assumptions!G59*12 | H9: =Drivers!H39*Assumptions!H59*12 | I9: =Drivers!I39*Assumptions!I59*12 | J9: =Drivers!J39*Assumptions!J59*12 | ... L9: =Drivers!L39*Assumptions!L59*12
A10: Infrastructure (AWS + CDN) | B10: base + egress | C10: =Assumptions!C58*12+C9*Assumptions!C60 | D10: =Assumptions!D58*12+D9*Assumptions!D60 | E10: =Assumptions!E58*12+E9*Assumptions!E60 | F10: =Assumptions!F58*12+F9*Assumptions!F60 | G10: =Assumptions!G58*12+G9*Assumptions!G60 | H10: =Assumptions!H58*12+H9*Assumptions!H60 | I10: =Assumptions!I58*12+I9*Assumptions!I60 | J10: =Assumptions!J58*12+J9*Assumptions!J60 | ... L10: =Assumptions!L58*12+L9*Assumptions!L60
A11: memo: same egress at CloudFront list | B11: the trap | C11: =Assumptions!C58*12+C9*Assumptions!C61 | D11: =Assumptions!D58*12+D9*Assumptions!D61 | E11: =Assumptions!E58*12+E9*Assumptions!E61 | F11: =Assumptions!F58*12+F9*Assumptions!F61 | G11: =Assumptions!G58*12+G9*Assumptions!G61 | H11: =Assumptions!H58*12+H9*Assumptions!H61 | I11: =Assumptions!I58*12+I9*Assumptions!I61 | J11: =Assumptions!J58*12+J9*Assumptions!J61 | ... L11: =Assumptions!L58*12+L9*Assumptions!L61
A12: Moderation | B12: items x rate | C12: =Drivers!C5*Assumptions!C63*12/1000*Assumptions!C62 | D12: =Drivers!D5*Assumptions!D63*12/1000*Assumptions!D62 | E12: =Drivers!E5*Assumptions!E63*12/1000*Assumptions!E62 | F12: =Drivers!F5*Assumptions!F63*12/1000*Assumptions!F62 | G12: =Drivers!G5*Assumptions!G63*12/1000*Assumptions!G62 | H12: =Drivers!H5*Assumptions!H63*12/1000*Assumptions!H62 | I12: =Drivers!I5*Assumptions!I63*12/1000*Assumptions!I62 | J12: =Drivers!J5*Assumptions!J63*12/1000*Assumptions!J62 | ... L12: =Drivers!L5*Assumptions!L63*12/1000*Assumptions!L62
A13: Athlete verification | B13: reviews x minutes x hourly | C13: =Drivers!C55*Assumptions!C87/60*(Assumptions!C67/Assumptions!C88) | D13: =Drivers!D55*Assumptions!D87/60*(Assumptions!D67/Assumptions!D88) | E13: =Drivers!E55*Assumptions!E87/60*(Assumptions!E67/Assumptions!E88) | F13: =Drivers!F55*Assumptions!F87/60*(Assumptions!F67/Assumptions!F88) | G13: =Drivers!G55*Assumptions!G87/60*(Assumptions!G67/Assumptions!G88) | H13: =Drivers!H55*Assumptions!H87/60*(Assumptions!H67/Assumptions!H88) | I13: =Drivers!I55*Assumptions!I87/60*(Assumptions!I67/Assumptions!I88) | J13: =Drivers!J55*Assumptions!J87/60*(Assumptions!J67/Assumptions!J88) | ... L13: =Drivers!L55*Assumptions!L87/60*(Assumptions!L67/Assumptions!L88)
A14: TOTAL COST OF SALES | C14: =C7+C8+C10+C12+C13 | D14: =D7+D8+D10+D12+D13 | E14: =E7+E8+E10+E12+E13 | F14: =F7+F8+F10+F12+F13 | G14: =G7+G8+G10+G12+G13 | H14: =H7+H8+H10+H12+H13 | I14: =I7+I8+I10+I12+I13 | J14: =J7+J8+J10+J12+J13 | ... L14: =L7+L8+L10+L12+L13
A16: OPERATING COSTS
A17: People | B17: FTE x loaded salary | C17: =Assumptions!C66*Assumptions!C67 | D17: =Assumptions!D66*Assumptions!D67 | E17: =Assumptions!E66*Assumptions!E67 | F17: =Assumptions!F66*Assumptions!F67 | G17: =Assumptions!G66*Assumptions!G67 | H17: =Assumptions!H66*Assumptions!H67 | I17: =Assumptions!I66*Assumptions!I67 | J17: =Assumptions!J66*Assumptions!J67 | ... L17: =Assumptions!L66*Assumptions!L67
A18: Athlete acquisition: niche | B18: gross adds x CAC | C18: =Drivers!C11*Assumptions!C19 | D18: =Drivers!D11*Assumptions!D19 | E18: =Drivers!E11*Assumptions!E19 | F18: =Drivers!F11*Assumptions!F19 | G18: =Drivers!G11*Assumptions!G19 | H18: =Drivers!H11*Assumptions!H19 | I18: =Drivers!I11*Assumptions!I19 | J18: =Drivers!J11*Assumptions!J19 | ... L18: =Drivers!L11*Assumptions!L19
A19: Athlete acquisition: popular | C19: =Drivers!C25*Assumptions!C31 | D19: =Drivers!D25*Assumptions!D31 | E19: =Drivers!E25*Assumptions!E31 | F19: =Drivers!F25*Assumptions!F31 | G19: =Drivers!G25*Assumptions!G31 | H19: =Drivers!H25*Assumptions!H31 | I19: =Drivers!I25*Assumptions!I31 | J19: =Drivers!J25*Assumptions!J31 | ... L19: =Drivers!L25*Assumptions!L31
A20: Sponsor acquisition | C20: =Drivers!C49*Assumptions!C37 | D20: =Drivers!D49*Assumptions!D37 | E20: =Drivers!E49*Assumptions!E37 | F20: =Drivers!F49*Assumptions!F37 | G20: =Drivers!G49*Assumptions!G37 | H20: =Drivers!H49*Assumptions!H37 | I20: =Drivers!I49*Assumptions!I37 | J20: =Drivers!J49*Assumptions!J37 | ... L20: =Drivers!L49*Assumptions!L37
A21: Total marketing / CAC | C21: =SUM(C18:C20) | D21: =SUM(D18:D20) | E21: =SUM(E18:E20) | F21: =SUM(F18:F20) | G21: =SUM(G18:G20) | H21: =SUM(H18:H20) | I21: =SUM(I18:I20) | J21: =SUM(J18:J20) | ... L21: =SUM(L18:L20)
A22: memo: athlete marketing per application | B22: CAC is per ADMITTED athlete | C22: =(C18+C19)/Drivers!C54 | D22: =(D18+D19)/Drivers!D54 | E22: =(E18+E19)/Drivers!E54 | F22: =(F18+F19)/Drivers!F54 | G22: =(G18+G19)/Drivers!G54 | H22: =(H18+H19)/Drivers!H54 | I22: =(I18+I19)/Drivers!I54 | J22: =(J18+J19)/Drivers!J54 | ... L22: =(L18+L19)/Drivers!L54
A23: Legal & compliance | C23: =Assumptions!C68 | D23: =Assumptions!D68 | E23: =Assumptions!E68 | F23: =Assumptions!F68 | G23: =Assumptions!G68 | H23: =Assumptions!H68 | I23: =Assumptions!I68 | J23: =Assumptions!J68 | ... L23: =Assumptions!L68
A24: Other opex | B24: % of revenue | C24: =Revenue!C26*Assumptions!C69 | D24: =Revenue!D26*Assumptions!D69 | E24: =Revenue!E26*Assumptions!E69 | F24: =Revenue!F26*Assumptions!F69 | G24: =Revenue!G26*Assumptions!G69 | H24: =Revenue!H26*Assumptions!H69 | I24: =Revenue!I26*Assumptions!I69 | J24: =Revenue!J26*Assumptions!J69 | ... L24: =Revenue!L26*Assumptions!L69
A25: TOTAL OPERATING COSTS | C25: =C17+C21+C23+C24 | D25: =D17+D21+D23+D24 | E25: =E17+E21+E23+E24 | F25: =F17+F21+F23+F24 | G25: =G17+G21+G23+G24 | H25: =H17+H21+H23+H24 | I25: =I17+I21+I23+I24 | J25: =J17+J21+J23+J24 | ... L25: =L17+L21+L23+L24

Sheet WorkingCap
A1: Working capital, capex and amortisation
C2: Input: change me | E2: Sourced fact | G2: Formula (this sheet) | I2: Formula (other sheet) | K2: Total
A3: Line | B3: Unit | C3: Y1 | D3: Y2 | E3: Y3 | F3: Y4 | G3: Y5 | H3: Y6 | I3: Y7 | J3: Y8 | K3: Y9 | L3: Y10
A4: WORKING CAPITAL
A5: Sponsor receivables | B5: SaaS+take x AR days/365 | C5: =(Revenue!C24+Revenue!C25)*Assumptions!C73/365 | D5: =(Revenue!D24+Revenue!D25)*Assumptions!D73/365 | E5: =(Revenue!E24+Revenue!E25)*Assumptions!E73/365 | F5: =(Revenue!F24+Revenue!F25)*Assumptions!F73/365 | G5: =(Revenue!G24+Revenue!G25)*Assumptions!G73/365 | H5: =(Revenue!H24+Revenue!H25)*Assumptions!H73/365 | I5: =(Revenue!I24+Revenue!I25)*Assumptions!I73/365 | J5: =(Revenue!J24+Revenue!J25)*Assumptions!J73/365 | ... L5: =(Revenue!L24+Revenue!L25)*Assumptions!L73/365
A6: Athlete payout float | B6: processed GMV owed, not yet paid | C6: =(Revenue!C10+Revenue!C15)*Assumptions!C72/365 | D6: =(Revenue!D10+Revenue!D15)*Assumptions!D72/365 | E6: =(Revenue!E10+Revenue!E15)*Assumptions!E72/365 | F6: =(Revenue!F10+Revenue!F15)*Assumptions!F72/365 | G6: =(Revenue!G10+Revenue!G15)*Assumptions!G72/365 | H6: =(Revenue!H10+Revenue!H15)*Assumptions!H72/365 | I6: =(Revenue!I10+Revenue!I15)*Assumptions!I72/365 | J6: =(Revenue!J10+Revenue!J15)*Assumptions!J72/365 | ... L6: =(Revenue!L10+Revenue!L15)*Assumptions!L72/365
A7: Trade payables | B7: opex x AP days/365 | C7: =Costs!C25*Assumptions!C74/365 | D7: =Costs!D25*Assumptions!D74/365 | E7: =Costs!E25*Assumptions!E74/365 | F7: =Costs!F25*Assumptions!F74/365 | G7: =Costs!G25*Assumptions!G74/365 | H7: =Costs!H25*Assumptions!H74/365 | I7: =Costs!I25*Assumptions!I74/365 | J7: =Costs!J25*Assumptions!J74/365 | ... L7: =Costs!L25*Assumptions!L74/365
A8: Net working capital | B8: AR - float - AP | C8: =C5-C6-C7 | D8: =D5-D6-D7 | E8: =E5-E6-E7 | F8: =F5-F6-F7 | G8: =G5-G6-G7 | H8: =H5-H6-H7 | I8: =I5-I6-I7 | J8: =J5-J6-J7 | ... L8: =L5-L6-L7
A9: Change in NWC | B9: cash impact | C9: =IF(1=1,C8,C8-C8) | D9: =IF(2=1,D8,D8-C8) | E9: =IF(3=1,E8,E8-D8) | F9: =IF(4=1,F8,F8-E8) | G9: =IF(5=1,G8,G8-F8) | H9: =IF(6=1,H8,H8-G8) | I9: =IF(7=1,I8,I8-H8) | J9: =IF(8=1,J8,J8-I8) | K9: =IF(9=1,K8,K8-J8) | L9: =IF(10=1,L8,L8-K8)
A11: CAPEX & AMORTISATION
A12: Capitalised development | B12: % of people cost | C12: =Costs!C17*Assumptions!C75 | D12: =Costs!D17*Assumptions!D75 | E12: =Costs!E17*Assumptions!E75 | F12: =Costs!F17*Assumptions!F75 | G12: =Costs!G17*Assumptions!G75 | H12: =Costs!H17*Assumptions!H75 | I12: =Costs!I17*Assumptions!I75 | J12: =Costs!J17*Assumptions!J75 | ... L12: =Costs!L17*Assumptions!L75
A13: Amortisation | B13: 3-yr straight line on trailing capex | C13: =SUM(OFFSET(C12,0,-MIN(Assumptions!C76-1,1-1),1,MIN(Assumptions!C76,1)))/Assumptions!C76 | D13: =SUM(OFFSET(D12,0,-MIN(Assumptions!D76-1,2-1),1,MIN(Assumptions!D76,2)))/Assumptions!D76 | E13: =SUM(OFFSET(E12,0,-MIN(Assumptions!E76-1,3-1),1,MIN(Assumptions!E76,3)))/Assumptions!E76 | F13: =SUM(OFFSET(F12,0,-MIN(Assumptions!F76-1,4-1),1,MIN(Assumptions!F76,4)))/Assumptions!F76 | G13: =SUM(OFFSET(G12,0,-MIN(Assumptions!G76-1,5-1),1,MIN(Assumptions!G76,5)))/Assumptions!G76 | H13: =SUM(OFFSET(H12,0,-MIN(Assumptions!H76-1,6-1),1,MIN(Assumptions!H76,6)))/Assumptions!H76 | I13: =SUM(OFFSET(I12,0,-MIN(Assumptions!I76-1,7-1),1,MIN(Assumptions!I76,7)))/Assumptions!I76 | J13: =SUM(OFFSET(J12,0,-MIN(Assumptions!J76-1,8-1),1,MIN(Assumptions!J76,8)))/Assumptions!J76 | K13: =SUM(OFFSET(K12,0,-MIN(Assumptions!K76-1,9-1),1,MIN(Assumptions!K76,9)))/Assumptions!K76 | L13: =SUM(OFFSET(L12,0,-MIN(Assumptions!L76-1,10-1),1,MIN(Assumptions!L76,10)))/Assumptions!L76
A14: Net intangible assets | B14: closing | C14: =C12-C13 | D14: =C14+D12-D13 | E14: =D14+E12-E13 | F14: =E14+F12-F13 | G14: =F14+G12-G13 | H14: =G14+H12-H13 | I14: =H14+I12-I13 | J14: =I14+J12-J13 | K14: =J14+K12-K13 | L14: =K14+L12-L13

Sheet P&L
A1: Income statement
C2: Input: change me | E2: Sourced fact | G2: Formula (this sheet) | I2: Formula (other sheet) | K2: Total
A3: Line | B3: Unit | C3: Y1 | D3: Y2 | E3: Y3 | F3: Y4 | G3: Y5 | H3: Y6 | I3: Y7 | J3: Y8 | K3: Y9 | L3: Y10
A4: Net revenue | C4: =Revenue!C26 | D4: =Revenue!D26 | E4: =Revenue!E26 | F4: =Revenue!F26 | G4: =Revenue!G26 | H4: =Revenue!H26 | I4: =Revenue!I26 | J4: =Revenue!J26 | ... L4: =Revenue!L26
A5: Cost of sales | C5: =-Costs!C14 | D5: =-Costs!D14 | E5: =-Costs!E14 | F5: =-Costs!F14 | G5: =-Costs!G14 | H5: =-Costs!H14 | I5: =-Costs!I14 | J5: =-Costs!J14 | ... L5: =-Costs!L14
A6: GROSS PROFIT | C6: =C4+C5 | D6: =D4+D5 | E6: =E4+E5 | F6: =F4+F5 | G6: =G4+G5 | H6: =H4+H5 | I6: =I4+I5 | J6: =J4+J5 | ... L6: =L4+L5
A7: Gross margin | C7: =C6/C4 | D7: =D6/D4 | E7: =E6/E4 | F7: =F6/F4 | G7: =G6/G4 | H7: =H6/H4 | I7: =I6/I4 | J7: =J6/J4 | ... L7: =L6/L4
A9: Operating costs | C9: =-Costs!C25 | D9: =-Costs!D25 | E9: =-Costs!E25 | F9: =-Costs!F25 | G9: =-Costs!G25 | H9: =-Costs!H25 | I9: =-Costs!I25 | J9: =-Costs!J25 | ... L9: =-Costs!L25
A10: EBITDA | C10: =C6+C9 | D10: =D6+D9 | E10: =E6+E9 | F10: =F6+F9 | G10: =G6+G9 | H10: =H6+H9 | I10: =I6+I9 | J10: =J6+J9 | ... L10: =L6+L9
A11: EBITDA margin | C11: =C10/C4 | D11: =D10/D4 | E11: =E10/E4 | F11: =F10/F4 | G11: =G10/G4 | H11: =H10/H4 | I11: =I10/I4 | J11: =J10/J4 | ... L11: =L10/L4
A12: Amortisation | C12: =-WorkingCap!C13 | D12: =-WorkingCap!D13 | E12: =-WorkingCap!E13 | F12: =-WorkingCap!F13 | G12: =-WorkingCap!G13 | H12: =-WorkingCap!H13 | I12: =-WorkingCap!I13 | J12: =-WorkingCap!J13 | ... L12: =-WorkingCap!L13
A13: EBIT | C13: =C10+C12 | D13: =D10+D12 | E13: =E10+E12 | F13: =F10+F12 | G13: =G10+G12 | H13: =H10+H12 | I13: =I10+I12 | J13: =J10+J12 | ... L13: =L10+L12
A15: TAX: with loss carryforward and the startup-rate step
A16: Losses brought forward | B16: accumulated | C16: =IF(1=1,0,MIN(0,C18)) | D16: =IF(2=1,0,MIN(0,C18)) | E16: =IF(3=1,0,MIN(0,D18)) | F16: =IF(4=1,0,MIN(0,E18)) | G16: =IF(5=1,0,MIN(0,F18)) | H16: =IF(6=1,0,MIN(0,G18)) | I16: =IF(7=1,0,MIN(0,H18)) | J16: =IF(8=1,0,MIN(0,I18)) | K16: =IF(9=1,0,MIN(0,J18)) | L16: =IF(10=1,0,MIN(0,K18))
A17: Taxable profit | B17: after offset | C17: =MAX(0,C13+C16) | D17: =MAX(0,D13+D16) | E17: =MAX(0,E13+E16) | F17: =MAX(0,F13+F16) | G17: =MAX(0,G13+G16) | H17: =MAX(0,H13+H16) | I17: =MAX(0,I13+I16) | J17: =MAX(0,J13+J16) | ... L17: =MAX(0,L13+L16)
A18: Losses carried forward | B18: running | C18: =MIN(0,C13) | D18: =MIN(0,D13+C18) | E18: =MIN(0,E13+D18) | F18: =MIN(0,F13+E18) | G18: =MIN(0,G13+F18) | H18: =MIN(0,H13+G18) | I18: =MIN(0,I13+H18) | J18: =MIN(0,J13+I18) | K18: =MIN(0,K13+J18) | L18: =MIN(0,L13+K18)
A19: Applicable tax rate | B19: 15% then 25% | C19: =IF(C17<=0,0,IF(COUNTIF($C17:C17,">0")<=Assumptions!C79,Assumptions!C77,Assumptions!C78)) | D19: =IF(D17<=0,0,IF(COUNTIF($C17:D17,">0")<=Assumptions!D79,Assumptions!D77,Assumptions!D78)) | E19: =IF(E17<=0,0,IF(COUNTIF($C17:E17,">0")<=Assumptions!E79,Assumptions!E77,Assumptions!E78)) | F19: =IF(F17<=0,0,IF(COUNTIF($C17:F17,">0")<=Assumptions!F79,Assumptions!F77,Assumptions!F78)) | G19: =IF(G17<=0,0,IF(COUNTIF($C17:G17,">0")<=Assumptions!G79,Assumptions!G77,Assumptions!G78)) | H19: =IF(H17<=0,0,IF(COUNTIF($C17:H17,">0")<=Assumptions!H79,Assumptions!H77,Assumptions!H78)) | I19: =IF(I17<=0,0,IF(COUNTIF($C17:I17,">0")<=Assumptions!I79,Assumptions!I77,Assumptions!I78)) | J19: =IF(J17<=0,0,IF(COUNTIF($C17:J17,">0")<=Assumptions!J79,Assumptions!J77,Assumptions!J78)) | ... L19: =IF(L17<=0,0,IF(COUNTIF($C17:L17,">0")<=Assumptions!L79,Assumptions!L77,Assumptions!L78))
A20: Tax charge | C20: =-C17*C19 | D20: =-D17*D19 | E20: =-E17*E19 | F20: =-F17*F19 | G20: =-G17*G19 | H20: =-H17*H19 | I20: =-I17*I19 | J20: =-J17*J19 | ... L20: =-L17*L19
A21: NET PROFIT | C21: =C13+C20 | D21: =D13+D20 | E21: =E13+E20 | F21: =F13+F20 | G21: =G13+G20 | H21: =H13+H20 | I21: =I13+I20 | J21: =J13+J20 | ... L21: =L13+L20

Sheet CashFlow
A1: Cash flow, indirect method
C2: Input: change me | E2: Sourced fact | G2: Formula (this sheet) | I2: Formula (other sheet) | K2: Total
A3: Line | B3: Unit | C3: Y1 | D3: Y2 | E3: Y3 | F3: Y4 | G3: Y5 | H3: Y6 | I3: Y7 | J3: Y8 | K3: Y9 | L3: Y10
A4: Net profit | C4: ='P&L'!C21 | D4: ='P&L'!D21 | E4: ='P&L'!E21 | F4: ='P&L'!F21 | G4: ='P&L'!G21 | H4: ='P&L'!H21 | I4: ='P&L'!I21 | J4: ='P&L'!J21 | ... L4: ='P&L'!L21
A5: Add back amortisation | C5: =WorkingCap!C13 | D5: =WorkingCap!D13 | E5: =WorkingCap!E13 | F5: =WorkingCap!F13 | G5: =WorkingCap!G13 | H5: =WorkingCap!H13 | I5: =WorkingCap!I13 | J5: =WorkingCap!J13 | ... L5: =WorkingCap!L13
A6: Change in working capital | C6: =-WorkingCap!C9 | D6: =-WorkingCap!D9 | E6: =-WorkingCap!E9 | F6: =-WorkingCap!F9 | G6: =-WorkingCap!G9 | H6: =-WorkingCap!H9 | I6: =-WorkingCap!I9 | J6: =-WorkingCap!J9 | ... L6: =-WorkingCap!L9
A7: OPERATING CASH FLOW | C7: =SUM(C4:C6) | D7: =SUM(D4:D6) | E7: =SUM(E4:E6) | F7: =SUM(F4:F6) | G7: =SUM(G4:G6) | H7: =SUM(H4:H6) | I7: =SUM(I4:I6) | J7: =SUM(J4:J6) | ... L7: =SUM(L4:L6)
A8: Capital expenditure | C8: =-WorkingCap!C12 | D8: =-WorkingCap!D12 | E8: =-WorkingCap!E12 | F8: =-WorkingCap!F12 | G8: =-WorkingCap!G12 | H8: =-WorkingCap!H12 | I8: =-WorkingCap!I12 | J8: =-WorkingCap!J12 | ... L8: =-WorkingCap!L12
A9: FREE CASH FLOW | C9: =C7+C8 | D9: =D7+D8 | E9: =E7+E8 | F9: =F7+F8 | G9: =G7+G8 | H9: =H7+H8 | I9: =I7+I8 | J9: =J7+J8 | ... L9: =L7+L8
A10: Cumulative free cash flow | C10: =C9 | D10: =C10+D9 | E10: =D10+E9 | F10: =E10+F9 | G10: =F10+G9 | H10: =G10+H9 | I10: =H10+I9 | J10: =I10+J9 | K10: =J10+K9 | L10: =K10+L9
A12: Equity raised | B12: see Funding | C12: =Funding!C4 | D12: =Funding!D4 | E12: =Funding!E4 | F12: =Funding!F4 | G12: =Funding!G4 | H12: =Funding!H4 | I12: =Funding!I4 | J12: =Funding!J4 | ... L12: =Funding!L4
A13: Opening cash | C13: =0 | D13: =C14 | E13: =D14 | F13: =E14 | G13: =F14 | H13: =G14 | I13: =H14 | J13: =I14 | K13: =J14 | L13: =K14
A14: CLOSING CASH | C14: =C13+C9+C12 | D14: =D13+D9+D12 | E14: =E13+E9+E12 | F14: =F13+F9+F12 | G14: =G13+G9+G12 | H14: =H13+H9+H12 | I14: =I13+I9+I12 | J14: =J13+J9+J12 | ... L14: =L13+L9+L12

Sheet BalanceSheet
A1: Balance sheet
C2: Input: change me | E2: Sourced fact | G2: Formula (this sheet) | I2: Formula (other sheet) | K2: Total
A3: Line | B3: Unit | C3: Y1 | D3: Y2 | E3: Y3 | F3: Y4 | G3: Y5 | H3: Y6 | I3: Y7 | J3: Y8 | K3: Y9 | L3: Y10
A4: ASSETS
A5: Cash | C5: =CashFlow!C14 | D5: =CashFlow!D14 | E5: =CashFlow!E14 | F5: =CashFlow!F14 | G5: =CashFlow!G14 | H5: =CashFlow!H14 | I5: =CashFlow!I14 | J5: =CashFlow!J14 | ... L5: =CashFlow!L14
A6: Sponsor receivables | C6: =WorkingCap!C5 | D6: =WorkingCap!D5 | E6: =WorkingCap!E5 | F6: =WorkingCap!F5 | G6: =WorkingCap!G5 | H6: =WorkingCap!H5 | I6: =WorkingCap!I5 | J6: =WorkingCap!J5 | ... L6: =WorkingCap!L5
A7: Net intangible assets | C7: =WorkingCap!C14 | D7: =WorkingCap!D14 | E7: =WorkingCap!E14 | F7: =WorkingCap!F14 | G7: =WorkingCap!G14 | H7: =WorkingCap!H14 | I7: =WorkingCap!I14 | J7: =WorkingCap!J14 | ... L7: =WorkingCap!L14
A8: TOTAL ASSETS | C8: =SUM(C5:C7) | D8: =SUM(D5:D7) | E8: =SUM(E5:E7) | F8: =SUM(F5:F7) | G8: =SUM(G5:G7) | H8: =SUM(H5:H7) | I8: =SUM(I5:I7) | J8: =SUM(J5:J7) | ... L8: =SUM(L5:L7)
A10: LIABILITIES
A11: Athlete payout float | C11: =WorkingCap!C6 | D11: =WorkingCap!D6 | E11: =WorkingCap!E6 | F11: =WorkingCap!F6 | G11: =WorkingCap!G6 | H11: =WorkingCap!H6 | I11: =WorkingCap!I6 | J11: =WorkingCap!J6 | ... L11: =WorkingCap!L6
A12: Trade payables | C12: =WorkingCap!C7 | D12: =WorkingCap!D7 | E12: =WorkingCap!E7 | F12: =WorkingCap!F7 | G12: =WorkingCap!G7 | H12: =WorkingCap!H7 | I12: =WorkingCap!I7 | J12: =WorkingCap!J7 | ... L12: =WorkingCap!L7
A13: TOTAL LIABILITIES | C13: =C11+C12 | D13: =D11+D12 | E13: =E11+E12 | F13: =F11+F12 | G13: =G11+G12 | H13: =H11+H12 | I13: =I11+I12 | J13: =J11+J12 | ... L13: =L11+L12
A15: EQUITY
A16: Paid-in capital | C16: =Funding!C4 | D16: =C16+Funding!D4 | E16: =D16+Funding!E4 | F16: =E16+Funding!F4 | G16: =F16+Funding!G4 | H16: =G16+Funding!H4 | I16: =H16+Funding!I4 | J16: =I16+Funding!J4 | K16: =J16+Funding!K4 | L16: =K16+Funding!L4
A17: Retained earnings | C17: ='P&L'!C21 | D17: =C17+'P&L'!D21 | E17: =D17+'P&L'!E21 | F17: =E17+'P&L'!F21 | G17: =F17+'P&L'!G21 | H17: =G17+'P&L'!H21 | I17: =H17+'P&L'!I21 | J17: =I17+'P&L'!J21 | K17: =J17+'P&L'!K21 | L17: =K17+'P&L'!L21
A18: TOTAL EQUITY | C18: =C16+C17 | D18: =D16+D17 | E18: =E16+E17 | F18: =F16+F17 | G18: =G16+G17 | H18: =H16+H17 | I18: =I16+I17 | J18: =J16+J17 | ... L18: =L16+L17
A19: Liabilities + equity | C19: =C13+C18 | D19: =D13+D18 | E19: =E13+E18 | F19: =F13+F18 | G19: =G13+G18 | H19: =H13+H18 | I19: =I13+I18 | J19: =J13+J18 | ... L19: =L13+L18
A20: BALANCE CHECK | B20: must be zero | C20: =ROUND(C8-C19,2) | D20: =ROUND(D8-D19,2) | E20: =ROUND(E8-E19,2) | F20: =ROUND(F8-F19,2) | G20: =ROUND(G8-G19,2) | H20: =ROUND(H8-H19,2) | I20: =ROUND(I8-I19,2) | J20: =ROUND(J8-J19,2) | ... L20: =ROUND(L8-L19,2)

Sheet Valuation
A1: Valuation, DCF, NPV, IRR and exit multiples
C2: Input: change me | E2: Sourced fact | G2: Formula (this sheet) | I2: Formula (other sheet) | K2: Total
A3: Line | B3: Unit | C3: Y1 | D3: Y2 | E3: Y3 | F3: Y4 | G3: Y5 | H3: Y6 | I3: Y7 | J3: Y8 | K3: Y9 | L3: Y10
A4: Free cash flow | B4: EUR | C4: =CashFlow!C9 | D4: =CashFlow!D9 | E4: =CashFlow!E9 | F4: =CashFlow!F9 | G4: =CashFlow!G9 | H4: =CashFlow!H9 | I4: =CashFlow!I9 | J4: =CashFlow!J9 | ... L4: =CashFlow!L9
A5: Discount factor | B5: 1/(1+WACC)^t | C5: =1/(1+Assumptions!$C$91)^1 | D5: =1/(1+Assumptions!$C$91)^2 | E5: =1/(1+Assumptions!$C$91)^3 | F5: =1/(1+Assumptions!$C$91)^4 | G5: =1/(1+Assumptions!$C$91)^5 | H5: =1/(1+Assumptions!$C$91)^6 | I5: =1/(1+Assumptions!$C$91)^7 | J5: =1/(1+Assumptions!$C$91)^8 | K5: =1/(1+Assumptions!$C$91)^9 | L5: =1/(1+Assumptions!$C$91)^10
A6: Discounted FCF | B6: EUR | C6: =C4*C5 | D6: =D4*D5 | E6: =E4*E5 | F6: =F4*F5 | G6: =G4*G5 | H6: =H4*H5 | I6: =I4*I5 | J6: =J4*J5 | ... L6: =L4*L5
A8: FCF incl. terminal value | B8: for the IRR below | C8: =C4+IF(1=10,$C$11,0) | D8: =D4+IF(2=10,$C$11,0) | E8: =E4+IF(3=10,$C$11,0) | F8: =F4+IF(4=10,$C$11,0) | G8: =G4+IF(5=10,$C$11,0) | H8: =H4+IF(6=10,$C$11,0) | I8: =I4+IF(7=10,$C$11,0) | J8: =J4+IF(8=10,$C$11,0) | K8: =K4+IF(9=10,$C$11,0) | L8: =L4+IF(10=10,$C$11,0)
A9: DCF
A10: PV of explicit forecast | C10: =SUM(C6:L6)
A11: Terminal value at Y10 | C11: =L4*(1+Assumptions!$C$92)/(Assumptions!$C$91-Assumptions!$C$92)
A12: PV of terminal value | C12: =C11*L5
A13: ENTERPRISE VALUE (DCF) | C13: =C10+C12
A15: RETURN METRICS
A16: NPV of FCF at WACC | C16: =NPV(Assumptions!$C$91,C4:L4)
A17: IRR of the plan | C17: =IRR(C4:L4)
A18: IRR incl. terminal value | C18: =IRR(C8:L8,0.3)
A20: EXIT MULTIPLE
A21: Y10 net revenue | C21: =Revenue!L26
A22: Exit value at Y10 | C22: =C21*Assumptions!$C$93
A23: Discounted to today | C23: =C22*L5
A25: SENSITIVITY: enterprise value by WACC and terminal growth
A26: Terminal growth \ WACC | C26: 0.18 | D26: 0.2 | E26: 0.22 | F26: 0.25 | G26: 0.28 | H26: 0.3
A27: 0.01 | C27: =CashFlow!C9/(1+0.18)^1+CashFlow!D9/(1+0.18)^2+CashFlow!E9/(1+0.18)^3+CashFlow!F9/(1+0.18)^4+CashFlow!G9/(1+0.18)^5+CashFlow!H9/(1+0.18)^6+CashFlow!I9/(1+0.18)^7+CashFlow!J9/(1+0.18)^8+CashFlow!K9/(1+0.18)^9+CashFlow!L9/(1+0.18)^10+CashFlow!L9*(1+0.01)/(0.18-0.01)/(1+0.18)^10 | D27: =CashFlow!C9/(1+0.2)^1+CashFlow!D9/(1+0.2)^2+CashFlow!E9/(1+0.2)^3+CashFlow!F9/(1+0.2)^4+CashFlow!G9/(1+0.2)^5+CashFlow!H9/(1+0.2)^6+CashFlow!I9/(1+0.2)^7+CashFlow!J9/(1+0.2)^8+CashFlow!K9/(1+0.2)^9+CashFlow!L9/(1+0.2)^10+CashFlow!L9*(1+0.01)/(0.2-0.01)/(1+0.2)^10 | E27: =CashFlow!C9/(1+0.22)^1+CashFlow!D9/(1+0.22)^2+CashFlow!E9/(1+0.22)^3+CashFlow!F9/(1+0.22)^4+CashFlow!G9/(1+0.22)^5+CashFlow!H9/(1+0.22)^6+CashFlow!I9/(1+0.22)^7+CashFlow!J9/(1+0.22)^8+CashFlow!K9/(1+0.22)^9+CashFlow!L9/(1+0.22)^10+CashFlow!L9*(1+0.01)/(0.22-0.01)/(1+0.22)^10 | F27: =CashFlow!C9/(1+0.25)^1+CashFlow!D9/(1+0.25)^2+CashFlow!E9/(1+0.25)^3+CashFlow!F9/(1+0.25)^4+CashFlow!G9/(1+0.25)^5+CashFlow!H9/(1+0.25)^6+CashFlow!I9/(1+0.25)^7+CashFlow!J9/(1+0.25)^8+CashFlow!K9/(1+0.25)^9+CashFlow!L9/(1+0.25)^10+CashFlow!L9*(1+0.01)/(0.25-0.01)/(1+0.25)^10 | G27: =CashFlow!C9/(1+0.28)^1+CashFlow!D9/(1+0.28)^2+CashFlow!E9/(1+0.28)^3+CashFlow!F9/(1+0.28)^4+CashFlow!G9/(1+0.28)^5+CashFlow!H9/(1+0.28)^6+CashFlow!I9/(1+0.28)^7+CashFlow!J9/(1+0.28)^8+CashFlow!K9/(1+0.28)^9+CashFlow!L9/(1+0.28)^10+CashFlow!L9*(1+0.01)/(0.28-0.01)/(1+0.28)^10 | H27: =CashFlow!C9/(1+0.3)^1+CashFlow!D9/(1+0.3)^2+CashFlow!E9/(1+0.3)^3+CashFlow!F9/(1+0.3)^4+CashFlow!G9/(1+0.3)^5+CashFlow!H9/(1+0.3)^6+CashFlow!I9/(1+0.3)^7+CashFlow!J9/(1+0.3)^8+CashFlow!K9/(1+0.3)^9+CashFlow!L9/(1+0.3)^10+CashFlow!L9*(1+0.01)/(0.3-0.01)/(1+0.3)^10
A28: 0.02 | C28: =CashFlow!C9/(1+0.18)^1+CashFlow!D9/(1+0.18)^2+CashFlow!E9/(1+0.18)^3+CashFlow!F9/(1+0.18)^4+CashFlow!G9/(1+0.18)^5+CashFlow!H9/(1+0.18)^6+CashFlow!I9/(1+0.18)^7+CashFlow!J9/(1+0.18)^8+CashFlow!K9/(1+0.18)^9+CashFlow!L9/(1+0.18)^10+CashFlow!L9*(1+0.02)/(0.18-0.02)/(1+0.18)^10 | D28: =CashFlow!C9/(1+0.2)^1+CashFlow!D9/(1+0.2)^2+CashFlow!E9/(1+0.2)^3+CashFlow!F9/(1+0.2)^4+CashFlow!G9/(1+0.2)^5+CashFlow!H9/(1+0.2)^6+CashFlow!I9/(1+0.2)^7+CashFlow!J9/(1+0.2)^8+CashFlow!K9/(1+0.2)^9+CashFlow!L9/(1+0.2)^10+CashFlow!L9*(1+0.02)/(0.2-0.02)/(1+0.2)^10 | E28: =CashFlow!C9/(1+0.22)^1+CashFlow!D9/(1+0.22)^2+CashFlow!E9/(1+0.22)^3+CashFlow!F9/(1+0.22)^4+CashFlow!G9/(1+0.22)^5+CashFlow!H9/(1+0.22)^6+CashFlow!I9/(1+0.22)^7+CashFlow!J9/(1+0.22)^8+CashFlow!K9/(1+0.22)^9+CashFlow!L9/(1+0.22)^10+CashFlow!L9*(1+0.02)/(0.22-0.02)/(1+0.22)^10 | F28: =CashFlow!C9/(1+0.25)^1+CashFlow!D9/(1+0.25)^2+CashFlow!E9/(1+0.25)^3+CashFlow!F9/(1+0.25)^4+CashFlow!G9/(1+0.25)^5+CashFlow!H9/(1+0.25)^6+CashFlow!I9/(1+0.25)^7+CashFlow!J9/(1+0.25)^8+CashFlow!K9/(1+0.25)^9+CashFlow!L9/(1+0.25)^10+CashFlow!L9*(1+0.02)/(0.25-0.02)/(1+0.25)^10 | G28: =CashFlow!C9/(1+0.28)^1+CashFlow!D9/(1+0.28)^2+CashFlow!E9/(1+0.28)^3+CashFlow!F9/(1+0.28)^4+CashFlow!G9/(1+0.28)^5+CashFlow!H9/(1+0.28)^6+CashFlow!I9/(1+0.28)^7+CashFlow!J9/(1+0.28)^8+CashFlow!K9/(1+0.28)^9+CashFlow!L9/(1+0.28)^10+CashFlow!L9*(1+0.02)/(0.28-0.02)/(1+0.28)^10 | H28: =CashFlow!C9/(1+0.3)^1+CashFlow!D9/(1+0.3)^2+CashFlow!E9/(1+0.3)^3+CashFlow!F9/(1+0.3)^4+CashFlow!G9/(1+0.3)^5+CashFlow!H9/(1+0.3)^6+CashFlow!I9/(1+0.3)^7+CashFlow!J9/(1+0.3)^8+CashFlow!K9/(1+0.3)^9+CashFlow!L9/(1+0.3)^10+CashFlow!L9*(1+0.02)/(0.3-0.02)/(1+0.3)^10
A29: 0.03 | C29: =CashFlow!C9/(1+0.18)^1+CashFlow!D9/(1+0.18)^2+CashFlow!E9/(1+0.18)^3+CashFlow!F9/(1+0.18)^4+CashFlow!G9/(1+0.18)^5+CashFlow!H9/(1+0.18)^6+CashFlow!I9/(1+0.18)^7+CashFlow!J9/(1+0.18)^8+CashFlow!K9/(1+0.18)^9+CashFlow!L9/(1+0.18)^10+CashFlow!L9*(1+0.03)/(0.18-0.03)/(1+0.18)^10 | D29: =CashFlow!C9/(1+0.2)^1+CashFlow!D9/(1+0.2)^2+CashFlow!E9/(1+0.2)^3+CashFlow!F9/(1+0.2)^4+CashFlow!G9/(1+0.2)^5+CashFlow!H9/(1+0.2)^6+CashFlow!I9/(1+0.2)^7+CashFlow!J9/(1+0.2)^8+CashFlow!K9/(1+0.2)^9+CashFlow!L9/(1+0.2)^10+CashFlow!L9*(1+0.03)/(0.2-0.03)/(1+0.2)^10 | E29: =CashFlow!C9/(1+0.22)^1+CashFlow!D9/(1+0.22)^2+CashFlow!E9/(1+0.22)^3+CashFlow!F9/(1+0.22)^4+CashFlow!G9/(1+0.22)^5+CashFlow!H9/(1+0.22)^6+CashFlow!I9/(1+0.22)^7+CashFlow!J9/(1+0.22)^8+CashFlow!K9/(1+0.22)^9+CashFlow!L9/(1+0.22)^10+CashFlow!L9*(1+0.03)/(0.22-0.03)/(1+0.22)^10 | F29: =CashFlow!C9/(1+0.25)^1+CashFlow!D9/(1+0.25)^2+CashFlow!E9/(1+0.25)^3+CashFlow!F9/(1+0.25)^4+CashFlow!G9/(1+0.25)^5+CashFlow!H9/(1+0.25)^6+CashFlow!I9/(1+0.25)^7+CashFlow!J9/(1+0.25)^8+CashFlow!K9/(1+0.25)^9+CashFlow!L9/(1+0.25)^10+CashFlow!L9*(1+0.03)/(0.25-0.03)/(1+0.25)^10 | G29: =CashFlow!C9/(1+0.28)^1+CashFlow!D9/(1+0.28)^2+CashFlow!E9/(1+0.28)^3+CashFlow!F9/(1+0.28)^4+CashFlow!G9/(1+0.28)^5+CashFlow!H9/(1+0.28)^6+CashFlow!I9/(1+0.28)^7+CashFlow!J9/(1+0.28)^8+CashFlow!K9/(1+0.28)^9+CashFlow!L9/(1+0.28)^10+CashFlow!L9*(1+0.03)/(0.28-0.03)/(1+0.28)^10 | H29: =CashFlow!C9/(1+0.3)^1+CashFlow!D9/(1+0.3)^2+CashFlow!E9/(1+0.3)^3+CashFlow!F9/(1+0.3)^4+CashFlow!G9/(1+0.3)^5+CashFlow!H9/(1+0.3)^6+CashFlow!I9/(1+0.3)^7+CashFlow!J9/(1+0.3)^8+CashFlow!K9/(1+0.3)^9+CashFlow!L9/(1+0.3)^10+CashFlow!L9*(1+0.03)/(0.3-0.03)/(1+0.3)^10
A30: 0.04 | C30: =CashFlow!C9/(1+0.18)^1+CashFlow!D9/(1+0.18)^2+CashFlow!E9/(1+0.18)^3+CashFlow!F9/(1+0.18)^4+CashFlow!G9/(1+0.18)^5+CashFlow!H9/(1+0.18)^6+CashFlow!I9/(1+0.18)^7+CashFlow!J9/(1+0.18)^8+CashFlow!K9/(1+0.18)^9+CashFlow!L9/(1+0.18)^10+CashFlow!L9*(1+0.04)/(0.18-0.04)/(1+0.18)^10 | D30: =CashFlow!C9/(1+0.2)^1+CashFlow!D9/(1+0.2)^2+CashFlow!E9/(1+0.2)^3+CashFlow!F9/(1+0.2)^4+CashFlow!G9/(1+0.2)^5+CashFlow!H9/(1+0.2)^6+CashFlow!I9/(1+0.2)^7+CashFlow!J9/(1+0.2)^8+CashFlow!K9/(1+0.2)^9+CashFlow!L9/(1+0.2)^10+CashFlow!L9*(1+0.04)/(0.2-0.04)/(1+0.2)^10 | E30: =CashFlow!C9/(1+0.22)^1+CashFlow!D9/(1+0.22)^2+CashFlow!E9/(1+0.22)^3+CashFlow!F9/(1+0.22)^4+CashFlow!G9/(1+0.22)^5+CashFlow!H9/(1+0.22)^6+CashFlow!I9/(1+0.22)^7+CashFlow!J9/(1+0.22)^8+CashFlow!K9/(1+0.22)^9+CashFlow!L9/(1+0.22)^10+CashFlow!L9*(1+0.04)/(0.22-0.04)/(1+0.22)^10 | F30: =CashFlow!C9/(1+0.25)^1+CashFlow!D9/(1+0.25)^2+CashFlow!E9/(1+0.25)^3+CashFlow!F9/(1+0.25)^4+CashFlow!G9/(1+0.25)^5+CashFlow!H9/(1+0.25)^6+CashFlow!I9/(1+0.25)^7+CashFlow!J9/(1+0.25)^8+CashFlow!K9/(1+0.25)^9+CashFlow!L9/(1+0.25)^10+CashFlow!L9*(1+0.04)/(0.25-0.04)/(1+0.25)^10 | G30: =CashFlow!C9/(1+0.28)^1+CashFlow!D9/(1+0.28)^2+CashFlow!E9/(1+0.28)^3+CashFlow!F9/(1+0.28)^4+CashFlow!G9/(1+0.28)^5+CashFlow!H9/(1+0.28)^6+CashFlow!I9/(1+0.28)^7+CashFlow!J9/(1+0.28)^8+CashFlow!K9/(1+0.28)^9+CashFlow!L9/(1+0.28)^10+CashFlow!L9*(1+0.04)/(0.28-0.04)/(1+0.28)^10 | H30: =CashFlow!C9/(1+0.3)^1+CashFlow!D9/(1+0.3)^2+CashFlow!E9/(1+0.3)^3+CashFlow!F9/(1+0.3)^4+CashFlow!G9/(1+0.3)^5+CashFlow!H9/(1+0.3)^6+CashFlow!I9/(1+0.3)^7+CashFlow!J9/(1+0.3)^8+CashFlow!K9/(1+0.3)^9+CashFlow!L9/(1+0.3)^10+CashFlow!L9*(1+0.04)/(0.3-0.04)/(1+0.3)^10
A31: 0.05 | C31: =CashFlow!C9/(1+0.18)^1+CashFlow!D9/(1+0.18)^2+CashFlow!E9/(1+0.18)^3+CashFlow!F9/(1+0.18)^4+CashFlow!G9/(1+0.18)^5+CashFlow!H9/(1+0.18)^6+CashFlow!I9/(1+0.18)^7+CashFlow!J9/(1+0.18)^8+CashFlow!K9/(1+0.18)^9+CashFlow!L9/(1+0.18)^10+CashFlow!L9*(1+0.05)/(0.18-0.05)/(1+0.18)^10 | D31: =CashFlow!C9/(1+0.2)^1+CashFlow!D9/(1+0.2)^2+CashFlow!E9/(1+0.2)^3+CashFlow!F9/(1+0.2)^4+CashFlow!G9/(1+0.2)^5+CashFlow!H9/(1+0.2)^6+CashFlow!I9/(1+0.2)^7+CashFlow!J9/(1+0.2)^8+CashFlow!K9/(1+0.2)^9+CashFlow!L9/(1+0.2)^10+CashFlow!L9*(1+0.05)/(0.2-0.05)/(1+0.2)^10 | E31: =CashFlow!C9/(1+0.22)^1+CashFlow!D9/(1+0.22)^2+CashFlow!E9/(1+0.22)^3+CashFlow!F9/(1+0.22)^4+CashFlow!G9/(1+0.22)^5+CashFlow!H9/(1+0.22)^6+CashFlow!I9/(1+0.22)^7+CashFlow!J9/(1+0.22)^8+CashFlow!K9/(1+0.22)^9+CashFlow!L9/(1+0.22)^10+CashFlow!L9*(1+0.05)/(0.22-0.05)/(1+0.22)^10 | F31: =CashFlow!C9/(1+0.25)^1+CashFlow!D9/(1+0.25)^2+CashFlow!E9/(1+0.25)^3+CashFlow!F9/(1+0.25)^4+CashFlow!G9/(1+0.25)^5+CashFlow!H9/(1+0.25)^6+CashFlow!I9/(1+0.25)^7+CashFlow!J9/(1+0.25)^8+CashFlow!K9/(1+0.25)^9+CashFlow!L9/(1+0.25)^10+CashFlow!L9*(1+0.05)/(0.25-0.05)/(1+0.25)^10 | G31: =CashFlow!C9/(1+0.28)^1+CashFlow!D9/(1+0.28)^2+CashFlow!E9/(1+0.28)^3+CashFlow!F9/(1+0.28)^4+CashFlow!G9/(1+0.28)^5+CashFlow!H9/(1+0.28)^6+CashFlow!I9/(1+0.28)^7+CashFlow!J9/(1+0.28)^8+CashFlow!K9/(1+0.28)^9+CashFlow!L9/(1+0.28)^10+CashFlow!L9*(1+0.05)/(0.28-0.05)/(1+0.28)^10 | H31: =CashFlow!C9/(1+0.3)^1+CashFlow!D9/(1+0.3)^2+CashFlow!E9/(1+0.3)^3+CashFlow!F9/(1+0.3)^4+CashFlow!G9/(1+0.3)^5+CashFlow!H9/(1+0.3)^6+CashFlow!I9/(1+0.3)^7+CashFlow!J9/(1+0.3)^8+CashFlow!K9/(1+0.3)^9+CashFlow!L9/(1+0.3)^10+CashFlow!L9*(1+0.05)/(0.3-0.05)/(1+0.3)^10

Sheet Funding
A1: Funding rounds and dilution
C2: Input: change me | E2: Sourced fact | G2: Formula (this sheet) | I2: Formula (other sheet) | K2: Total
A3: Line | B3: Unit | C3: Y1 | D3: Y2 | E3: Y3 | F3: Y4 | G3: Y5 | H3: Y6 | I3: Y7 | J3: Y8 | K3: Y9 | L3: Y10
A4: Equity raised | B4: EUR | C4: 600000 | D4: 0 | E4: 0 | F4: 2000000 | G4: 0 | H4: 8000000 | I4: 0 | J4: 0 | K4: 0 | L4: 0
A5: Pre-money valuation | B5: EUR | C5: 2500000 | D5: 0 | E5: 0 | F5: 10000000 | G5: 0 | H5: 40000000 | I5: 0 | J5: 0 | K5: 0 | L5: 0
